Workbook

Sheet 00 Read Me
A1: Clarify AI — Enterprise QA Testing Workbook | J1: Dashboard | K1: NAV | L1: Features | M1: Bugs | N1: Launch | O1: Smoke | P1: Creds | Q1: Env | R1: Playbooks | S1: Cases | T1: Sign-Off
A4: Application | B4: Clarify AI
A5: Description | B5: AI-powered interview preparation & rehearsal platform with Indian gov-exam MCQ mock tests, live coaching overlay, and dual Stripe/Razorpay billing.
A6: Tech stack | B6: React 18 + TypeScript + Vite + Tailwind/shadcn · Supabase (Auth, Postgres+RLS, Edge/Deno, Storage, Realtime) · Electron · Deepgram · Gemini/OpenAI/Anthropic · Stripe + Razorpay
A7: Portals | B7: Marketing · Auth · Candidate App · Admin · Electron Overlay
A8: Roles | B8: Guest · Free User · Pro User · Max User · Admin
A9: Version under test | B9: 1.0.0 / 1.0.0-beta
A10: Generated | B10: 2026-07-29
A12: HOW TO USE
A13: 1 | B13: Start at NAV Hub or 01 Dashboard — KPIs + charts.
A14: 2 | B14: QA opens QA Tasks — pick your rows (Shreya / Raj). Execute linked TCs on 04.
A15: 3 | B15: On Fail: set Pass/Fail=Fail on 04 → add a row on 06 Bug Tracker (Reported By = you, Assigned To = a Developer).
A16: 4 | B16: Dev Tasks auto-mirrors 06 — developers see Needs Dev Action=Yes. Filter that column.
A17: 5 | B17: Dev sets Bug Status=Fixed or Retest on 06 → QA retests → Closed. Fill Daily Log daily.
A18: 6 | B18: Complete 19 Production Readiness and 20 Release Sign-Off for Go/No-Go.
A19: 7 | B19: Slicer tip: AutoFilter on Bug Tracker / Dev Tasks / QA Tasks (Status, Owner, Priority).
A21: QA TEAM (production)
B22: Shreya Patil — Practice Coach, Overlay, Mock, Sessions/Debrief, Documents, UI/UX, Electron
B23: Raj Balani — Auth, Billing, Gov Exams, Admin, Prep Lab, Security, Regression
A24: DEV TEAM
B25: Dev Lead · Live Coach Dev · Platform Dev · GovExams Dev · Desktop Dev — see Dev Team sheet
A26: Green | B26: Pass / Yes / Closed / Done
A27: Red | B27: Fail / No / Critical / Blocked
A28: Yellow | B28: In Progress / Open / Medium / Queued
A29: Gray | B29: Not Started / Not Run
A30: Blue | B30: Completed / Passed / Ready
A32: SCALING
B33: One row per entity; filters + freeze panes. Dashboard / Dev Tasks formulas scan to row 5000 / 152.
A34: Google Sheets | B34: Upload .xlsx to Drive → Open with Google Sheets. Hyperlinks transfer; confirm Lists ranges after import.
A36: SHEET INDEX (click sheet tabs or use NAV Hub)
A37: NAV Hub | B37: Clickable map of every sheet — start here
A38: 01 Dashboard | B38: Executive KPIs + charts (Power BI style)
A39: QA Tasks | B39: Shreya & Raj execution queue
A40: Dev Team | B40: Developer roster + open-bug counts
A41: Dev Tasks | B41: Live mirror of Bug Tracker for engineers
A42: 02 Module Master | B42: 20 Clarify modules
A43: 03 Feature Inventory | B43: 114 features + routes + how-it-works
A44: 04 Test Case Repository | B44: Executable cases
A45: 05 E2E User Flows | B45: Cross-module journeys
A46: 06 Bug Tracker | B46: Defect lifecycle — source of truth
...

Sheet NAV Hub
A1: NAV Hub — Clarify AI QA Workbook (Power BI style) | J1: Dashboard | K1: ● NAV | L1: Features | M1: Bugs | N1: Launch | O1: Smoke | P1: Creds | Q1: Env | R1: Playbooks | S1: Cases | T1: Sign-Off
A2: Click any link to jump. Treat AutoFilter columns on Features/Bugs as slicers.
A4: Executive
A5: 01 Dashboard | B5: KPIs, charts, inventory snapshot | C5: Open →
A6: 24 Launch Status | B6: Fixed / Open / Blocked rollup | C6: Open →
A7: 20 Release Sign-Off | B7: Go / No-Go | C7: Open →
A8: 19 Production Readiness | B8: Module readiness % | C8: Open →
A10: Scope & Coverage
A11: 02 Module Master | B11: 20 modules | C11: Open →
A12: 03 Feature Inventory | B12: Routes, deep links, how-it-works | C12: Open →
A13: 23 Module Playbooks | B13: Happy-path runbooks | C13: Open →
A14: 17 Role Based Testing | B14: Plan gates | C14: Open →
A16: Execution
A17: QA Tasks | B17: Shreya & Raj task board | C17: Open →
A18: 04 Test Case Repository | B18: Case library | C18: Open →
A19: 05 E2E User Flows | B19: Golden paths | C19: Open →
A20: 25 Smoke Pack | B20: Must-pass (~20) | C20: Open →
A21: 18 Regression Testing | B21: Release pack | C21: Open →
A22: Daily Log | B22: Trend feed | C22: Open →
A24: Defects & Quality
A25: 06 Bug Tracker | B25: Lifecycle (source of truth) | C25: Open →
A26: Dev Tasks | B26: Live bug mirror for developers | C26: Open →
A27: Dev Team | B27: Dev roster + load | C27: Open →
A28: 07 UI-UX Testing | B28: Visual / a11y | C28: Open →
A29: 08 Mobile Responsiveness | B29: Breakpoints | C29: Open →
A30: 13 Performance Testing | B30: Latency | C30: Open →
A32: Platform
A33: 09 API Testing | B33: Edge functions | C33: Open →
A34: 10 Database Validation | B34: Schema / RLS | C34: Open →
A35: 11 Authentication Testing | B35: Auth + MFA | C35: Open →
A36: 12 Security Testing | B36: OWASP-style | C36: Open →
A38: Domains
A39: 14 Live Coaching Testing | B39: Coach + overlay | C39: Open →
A40: 15 Gov Exam Mock Testing | B40: MCQ engine | C40: Open →
A41: 16 Billing Credits Testing | B41: Stripe / Razorpay | C41: Open →
A43: Ops & Hire Pack
A44: 21 Test Credentials | B44: Placeholders only | C44: Open →
A45: 22 Environments | B45: URLs + secrets checklist | C45: Open →
A46: QA Team | B46: Shreya Patil · Raj Balani | C46: Open →
A47: 00 Read Me | B47: How to use | C47: Open →
...

Sheet 01 Dashboard
A1: Clarify AI — QA Executive Dashboard (Power BI style) | J1: ● Dashboard | K1: NAV | L1: Features | M1: Bugs | N1: Launch | O1: Smoke | P1: Creds | Q1: Env | R1: Playbooks | S1: Cases | T1: Sign-Off
A2: Synced 2026-07-29 · Formula KPIs + inventory snapshot · Use AutoFilter on Features/Bugs as slicers · Click NAV Hub for sheet map
A3: KEY PERFORMANCE INDICATORS | F3: Count | I3: Daily Progress | N3: QA Person | O3: Actual Hours
A4: Total Modules | B4: =IFERROR(COUNTA('02 Module Master'!A3:A5000)-COUNTIF('02 Module Master'!A3:A5000,"TOTAL"),0) | C4: PROGRESS BARS | F4: Passed | G4: =IFERROR(B7,0) | I4: Date | J4: Executed | K4: Passed | L4: Hours | N4: Shreya Patil | O4: =IFERROR(SUMIF('04 Test Case Repository'!S$3:S$5000,N4,'04 Test Case Repository'!U$3:U$5000),0)
A5: Total Features | B5: =IFERROR(COUNTA('03 Feature Inventory'!A3:A5000)-COUNTIF('03 Feature Inventory'!A3:A5000,"TOTAL"),0) | C5: Pass Rate | D5: =IFERROR(REPT("#",MAX(0,MIN(10,ROUND(N(B16)*10,0))))&REPT("-",10-MAX(0,MIN(10,ROUND(N(B16)*10,0)))),REPT("-",10)) | F5: Failed | G5: =IFERROR(B8,0) | I5: =IFERROR('Daily Log'!A3,"") | J5: =IFERROR('Daily Log'!C3,0) | K5: =IFERROR('Daily Log'!D3,0) | L5: =IFERROR('Daily Log'!I3,0) | N5: Raj Balani | O5: =IFERROR(SUMIF('04 Test Case Repository'!S$3:S$5000,N5,'04 Test Case Repository'!U$3:U$5000),0)
A6: Total Test Cases | B6: =IFERROR(COUNTA('04 Test Case Repository'!A3:A5000)-COUNTIF('04 Test Case Repository'!A3:A5000,"TOTAL"),0) | C6: QA Progress | D6: =IFERROR(REPT("#",MAX(0,MIN(10,ROUND(N(B18)*10,0))))&REPT("-",10-MAX(0,MIN(10,ROUND(N(B18)*10,0)))),REPT("-",10)) | F6: Blocked | G6: =IFERROR(B9,0) | I6: =IFERROR('Daily Log'!A4,"") | J6: =IFERROR('Daily Log'!C4,0) | K6: =IFERROR('Daily Log'!D4,0) | L6: =IFERROR('Daily Log'!I4,0)
A7: Passed | B7: =IFERROR(COUNTIF('04 Test Case Repository'!P3:P5000,"Pass"),0) | C7: Prod Ready | D7: =IFERROR(REPT("#",MAX(0,MIN(10,ROUND(N(B19)*10,0))))&REPT("-",10-MAX(0,MIN(10,ROUND(N(B19)*10,0)))),REPT("-",10)) | F7: Not Executed | G7: =IFERROR(B10,0) | I7: =IFERROR('Daily Log'!A5,"") | J7: =IFERROR('Daily Log'!C5,0) | K7: =IFERROR('Daily Log'!D5,0) | L7: =IFERROR('Daily Log'!I5,0)
A8: Failed | B8: =IFERROR(COUNTIF('04 Test Case Repository'!P3:P5000,"Fail"),0) | C8: Module Complete | D8: =IFERROR(REPT("#",MAX(0,MIN(10,ROUND(IFERROR(COUNTIF('02 Module Master'!H3:H5000,"Completed")/MAX(1,COUNTA('02 Module Master'!A3:A5000)),0)*10,0))))&REPT("-",10-MAX(0,MIN(10,ROUND(IFERROR(COUNTIF('02 Module Master'!H3:H5000,"Completed")/MAX(1,COUNTA('02 Module Master'!A3:A5000)),0)*10,0)))),REPT("-",10)) | I8: =IFERROR('Daily Log'!A6,"") | J8: =IFERROR('Daily Log'!C6,0) | K8: =IFERROR('Daily Log'!D6,0) | L8: =IFERROR('Daily Log'!I6,0)
A9: Blocked | B9: =IFERROR(COUNTIF('04 Test Case Repository'!P3:P5000,"Blocked"),0) | C9: Hours Burn | D9: =IFERROR(REPT("#",MAX(0,MIN(10,ROUND(IF(B20=0,0,MIN(1,B21/B20))*10,0))))&REPT("-",10-MAX(0,MIN(10,ROUND(IF(B20=0,0,MIN(1,B21/B20))*10,0)))),REPT("-",10)) | F9: Count | I9: =IFERROR('Daily Log'!A7,"") | J9: =IFERROR('Daily Log'!C7,0) | K9: =IFERROR('Daily Log'!D7,0) | L9: =IFERROR('Daily Log'!I7,0)
A10: Not Executed | B10: =IFERROR(COUNTIF('04 Test Case Repository'!P3:P5000,"Not Run"),0) | F10: Critical | G10: =IFERROR(B12,0) | I10: =IFERROR('Daily Log'!A8,"") | J10: =IFERROR('Daily Log'!C8,0) | K10: =IFERROR('Daily Log'!D8,0) | L10: =IFERROR('Daily Log'!I8,0)
A11: In Progress | B11: =IFERROR(COUNTIF('04 Test Case Repository'!Q3:Q5000,"In Progress"),0) | F11: High | G11: =IFERROR(B13,0) | I11: =IFERROR('Daily Log'!A9,"") | J11: =IFERROR('Daily Log'!C9,0) | K11: =IFERROR('Daily Log'!D9,0) | L11: =IFERROR('Daily Log'!I9,0)
A12: Critical Bugs | B12: =IFERROR(COUNTIFS('06 Bug Tracker'!J3:J5000,"Critical",'06 Bug Tracker'!L3:L5000,"<>Closed"),0) | F12: Medium | G12: =IFERROR(B14,0) | I12: Open NAV Hub
A13: High Bugs | B13: =IFERROR(COUNTIFS('06 Bug Tracker'!J3:J5000,"High",'06 Bug Tracker'!L3:L5000,"<>Closed"),0) | F13: Low | G13: =IFERROR(B15,0) | I13: QA Tasks (Shreya/Raj)
A14: Medium Bugs | B14: =IFERROR(COUNTIFS('06 Bug Tracker'!J3:J5000,"Medium",'06 Bug Tracker'!L3:L5000,"<>Closed"),0) | I14: Dev Tasks (bug mirror)
A15: Low Bugs | B15: =IFERROR(COUNTIFS('06 Bug Tracker'!J3:J5000,"Low",'06 Bug Tracker'!L3:L5000,"<>Closed"),0) | F15: Module | G15: Completion % | I15: Bug Tracker
A16: Overall Pass % | B16: =IFERROR(IF((B7+B8+B9)=0,0,B7/(B7+B8+B9)),0) | F16: Auth & Onboarding | G16: =IFERROR(IF('02 Module Master'!I3=0,0,'02 Module Master'!J3/'02 Module Master'!I3),0) | I16: Smoke Pack
A17: Overall Fail % | B17: =IFERROR(IF((B7+B8+B9)=0,0,B8/(B7+B8+B9)),0) | F17: Dashboard | G17: =IFERROR(IF('02 Module Master'!I4=0,0,'02 Module Master'!J4/'02 Module Master'!I4),0) | I17: Launch Status
A18: QA Progress % | B18: =IFERROR(IF(B6=0,0,(B7+B8+B9+B11)/B6),0) | F18: Live Practice Coach | G18: =IFERROR(IF('02 Module Master'!I5=0,0,'02 Module Master'!J5/'02 Module Master'!I5),0)
A19: Production Readiness % | B19: =IFERROR(AVERAGEIF('19 Production Readiness'!A3:A5000,"<>",'19 Production Readiness'!R3:R5000),0) | F19: Mock Interview | G19: =IFERROR(IF('02 Module Master'!I6=0,0,'02 Module Master'!J6/'02 Module Master'!I6),0)
A20: Est Hours (Total) | B20: =IFERROR(SUM('04 Test Case Repository'!T3:T5000),0) | F20: Sessions & Debriefs | G20: =IFERROR(IF('02 Module Master'!I7=0,0,'02 Module Master'!J7/'02 Module Master'!I7),0)
A21: Actual Hours (Total) | B21: =IFERROR(SUM('04 Test Case Repository'!U3:U5000),0) | F21: Analytics & Usage | G21: =IFERROR(IF('02 Module Master'!I8=0,0,'02 Module Master'!J8/'02 Module Master'!I8),0)
A22: Hours Variance | B22: =IFERROR(B21-B20,0) | F22: Prep Lab | G22: =IFERROR(IF('02 Module Master'!I9=0,0,'02 Module Master'!J9/'02 Module Master'!I9),0)
A23: QA Team Size | B23: =IFERROR(COUNTA('QA Team'!A3:A50)-COUNTIF('QA Team'!A3:A50,"TOTAL"),0) | F23: Documents & Resumes | G23: =IFERROR(IF('02 Module Master'!I10=0,0,'02 Module Master'!J10/'02 Module Master'!I10),0)
A24: QA Tasks Open | B24: =IFERROR(COUNTIFS('QA Tasks'!H3:H5000,"<>Done",'QA Tasks'!H3:H5000,"<>"),0) | F24: Answer Bank | G24: =IFERROR(IF('02 Module Master'!I11=0,0,'02 Module Master'!J11/'02 Module Master'!I11),0)
A25: Dev Action Queue | B25: =IFERROR(COUNTIF('Dev Tasks'!I3:I152,"Yes"),0) | F25: Interviews & Calendar | G25: =IFERROR(IF('02 Module Master'!I12=0,0,'02 Module Master'!J12/'02 Module Master'!I12),0)
A26: Shreya Open Bugs | B26: =IFERROR(COUNTIFS('06 Bug Tracker'!N3:N5000,"Shreya Patil",'06 Bug Tracker'!L3:L5000,"<>Closed",'06 Bug Tracker'!L3:L5000,"<>Won't Fix"),0) | F26: Company Research | G26: =IFERROR(IF('02 Module Master'!I13=0,0,'02 Module Master'!J13/'02 Module Master'!I13),0)
A27: Raj Open Bugs | B27: =IFERROR(COUNTIFS('06 Bug Tracker'!N3:N5000,"Raj Balani",'06 Bug Tracker'!L3:L5000,"<>Closed",'06 Bug Tracker'!L3:L5000,"<>Won't Fix"),0) | F27: Notifications & Profile | G27: =IFERROR(IF('02 Module Master'!I14=0,0,'02 Module Master'!J14/'02 Module Master'!I14),0)
F28: Referrals & Guide | G28: =IFERROR(IF('02 Module Master'!I15=0,0,'02 Module Master'!J15/'02 Module Master'!I15),0)
F29: Gov Exam Mock Tests | G29: =IFERROR(IF('02 Module Master'!I16=0,0,'02 Module Master'!J16/'02 Module Master'!I16),0)
F30: Settings | G30: =IFERROR(IF('02 Module Master'!I17=0,0,'02 Module Master'!J17/'02 Module Master'!I17),0)
F31: Admin Portal | G31: =IFERROR(IF('02 Module Master'!I18=0,0,'02 Module Master'!J18/'02 Module Master'!I18),0)
F32: Marketing Site | G32: =IFERROR(IF('02 Module Master'!I19=0,0,'02 Module Master'!J19/'02 Module Master'!I19),0)
F33: Billing & Credits | G33: =IFERROR(IF('02 Module Master'!I20=0,0,'02 Module Master'!J20/'02 Module Master'!I20),0)
F34: Electron Desktop Overlay | G34: =IFERROR(IF('02 Module Master'!I21=0,0,'02 Module Master'!J21/'02 Module Master'!I21),0)
F35: Security & Platform | G35: =IFERROR(IF('02 Module Master'!I22=0,0,'02 Module Master'!J22/'02 Module Master'!I22),0)

Sheet QA Tasks
A1: QA Tasks — Shreya Patil & Raj Balani work queue | J1: Dashboard | K1: NAV | L1: Features | M1: Bugs | N1: Launch | O1: Smoke | P1: Creds | Q1: Env | R1: Playbooks | S1: Cases | T1: Sign-Off
A2: Task ID | B2: QA Owner | C2: Module | D2: Task Type | E2: Title | F2: Linked TC / Flow | G2: Priority | H2: Status | I2: Due Date | J2: Est Hours | K2: Actual Hours | L2: Linked Bug ID | M2: Fails Linked (auto) | N2: Notes
A3: QAT-001 | B3: Raj Balani | C3: Auth & Onboarding | D3: Functional | E3: Execute Auth & Onboarding pack — Email/OAuth login, MFA, 5-step onboarding | F3: See 04 / domain sheets for MOD-01 | G3: Critical | H3: Not Started | I3: 46240 | J3: 4 | K3: 0 | M3: =IFERROR(COUNTIFS('06 Bug Tracker'!N$3:N$5000,B3,'06 Bug Tracker'!L$3:L$5000,"<>Closed",'06 Bug Tracker'!L$3:L$5000,"<>Won't Fix",'06 Bug Tracker'!L$3:L$5000,"<>Duplicate"),0) | N3: Mark Fail on TC → create Bug in 06 → Bug ID appears here & on Dev Tasks
A4: QAT-002 | B4: Shreya Patil | C4: Dashboard | D4: Functional | E4: Execute Dashboard pack — Home KPIs, sessions, credits, upcoming interview | F4: See 04 / domain sheets for MOD-02 | G4: High | H4: Not Started | I4: 46241 | J4: 4 | K4: 0 | M4: =IFERROR(COUNTIFS('06 Bug Tracker'!N$3:N$5000,B4,'06 Bug Tracker'!L$3:L$5000,"<>Closed",'06 Bug Tracker'!L$3:L$5000,"<>Won't Fix",'06 Bug Tracker'!L$3:L$5000,"<>Duplicate"),0) | N4: Mark Fail on TC → create Bug in 06 → Bug ID appears here & on Dev Tasks
A5: QAT-003 | B5: Shreya Patil | C5: Live Practice Coach | D5: Functional | E5: Execute Live Practice Coach pack — Deepgram STT + AI hints/answers + overlay | F5: See 04 / domain sheets for MOD-03 | G5: Critical | H5: Not Started | I5: 46242 | J5: 4 | K5: 0 | M5: =IFERROR(COUNTIFS('06 Bug Tracker'!N$3:N$5000,B5,'06 Bug Tracker'!L$3:L$5000,"<>Closed",'06 Bug Tracker'!L$3:L$5000,"<>Won't Fix",'06 Bug Tracker'!L$3:L$5000,"<>Duplicate"),0) | N5: Mark Fail on TC → create Bug in 06 → Bug ID appears here & on Dev Tasks
A6: QAT-004 | B6: Shreya Patil | C6: Mock Interview | D6: Functional | E6: Execute Mock Interview pack — Timed mock sessions with AI scoring | F6: See 04 / domain sheets for MOD-04 | G6: High | H6: Not Started | I6: 46243 | J6: 4 | K6: 0 | M6: =IFERROR(COUNTIFS('06 Bug Tracker'!N$3:N$5000,B6,'06 Bug Tracker'!L$3:L$5000,"<>Closed",'06 Bug Tracker'!L$3:L$5000,"<>Won't Fix",'06 Bug Tracker'!L$3:L$5000,"<>Duplicate"),0) | N6: Mark Fail on TC → create Bug in 06 → Bug ID appears here & on Dev Tasks
A7: QAT-005 | B7: Shreya Patil | C7: Sessions & Debriefs | D7: Functional | E7: Execute Sessions & Debriefs pack — History, detail, AI debrief, scorecard share | F7: See 04 / domain sheets for MOD-05 | G7: High | H7: Not Started | I7: 46239 | J7: 4 | K7: 0 | M7: =IFERROR(COUNTIFS('06 Bug Tracker'!N$3:N$5000,B7,'06 Bug Tracker'!L$3:L$5000,"<>Closed",'06 Bug Tracker'!L$3:L$5000,"<>Won't Fix",'06 Bug Tracker'!L$3:L$5000,"<>Duplicate"),0) | N7: Mark Fail on TC → create Bug in 06 → Bug ID appears here & on Dev Tasks
A8: QAT-006 | B8: Raj Balani | C8: Analytics & Usage | D8: Functional | E8: Execute Analytics & Usage pack — Trends, WPM, fillers, credit usage | F8: See 04 / domain sheets for MOD-06 | G8: Medium | H8: Not Started | I8: 46240 | J8: 4 | K8: 0 | M8: =IFERROR(COUNTIFS('06 Bug Tracker'!N$3:N$5000,B8,'06 Bug Tracker'!L$3:L$5000,"<>Closed",'06 Bug Tracker'!L$3:L$5000,"<>Won't Fix",'06 Bug Tracker'!L$3:L$5000,"<>Duplicate"),0) | N8: Mark Fail on TC → create Bug in 06 → Bug ID appears here & on Dev Tasks
A9: QAT-007 | B9: Raj Balani | C9: Prep Lab | D9: Functional | E9: Execute Prep Lab pack — STAR, rephraser, polish, company Qs | F9: See 04 / domain sheets for MOD-07 | G9: High | H9: Not Started | I9: 46241 | J9: 4 | K9: 0 | M9: =IFERROR(COUNTIFS('06 Bug Tracker'!N$3:N$5000,B9,'06 Bug Tracker'!L$3:L$5000,"<>Closed",'06 Bug Tracker'!L$3:L$5000,"<>Won't Fix",'06 Bug Tracker'!L$3:L$5000,"<>Duplicate"),0) | N9: Mark Fail on TC → create Bug in 06 → Bug ID appears here & on Dev Tasks
A10: QAT-008 | B10: Shreya Patil | C10: Documents & Resumes | D10: Functional | E10: Execute Documents & Resumes pack — Upload, parse-resume, gap analysis, OCR | F10: See 04 / domain sheets for MOD-08 | G10: High | H10: Not Started | I10: 46242 | J10: 4 | K10: 0 | M10: =IFERROR(COUNTIFS('06 Bug Tracker'!N$3:N$5000,B10,'06 Bug Tracker'!L$3:L$5000,"<>Closed",'06 Bug Tracker'!L$3:L$5000,"<>Won't Fix",'06 Bug Tracker'!L$3:L$5000,"<>Duplicate"),0) | N10: Mark Fail on TC → create Bug in 06 → Bug ID appears here & on Dev Tasks
A11: QAT-009 | B11: Raj Balani | C11: Answer Bank | D11: Functional | E11: Execute Answer Bank pack — STAR library + AI generate via prep-tool | F11: See 04 / domain sheets for MOD-09 | G11: Medium | H11: Not Started | I11: 46243 | J11: 4 | K11: 0 | M11: =IFERROR(COUNTIFS('06 Bug Tracker'!N$3:N$5000,B11,'06 Bug Tracker'!L$3:L$5000,"<>Closed",'06 Bug Tracker'!L$3:L$5000,"<>Won't Fix",'06 Bug Tracker'!L$3:L$5000,"<>Duplicate"),0) | N11: Mark Fail on TC → create Bug in 06 → Bug ID appears here & on Dev Tasks
A12: QAT-010 | B12: Shreya Patil | C12: Interviews & Calendar | D12: Functional | E12: Execute Interviews & Calendar pack — Manual interviews + Google Calendar sync | F12: See 04 / domain sheets for MOD-10 | G12: High | H12: Not Started | I12: 46239 | J12: 4 | K12: 0 | M12: =IFERROR(COUNTIFS('06 Bug Tracker'!N$3:N$5000,B12,'06 Bug Tracker'!L$3:L$5000,"<>Closed",'06 Bug Tracker'!L$3:L$5000,"<>Won't Fix",'06 Bug Tracker'!L$3:L$5000,"<>Duplicate"),0) | N12: Mark Fail on TC → create Bug in 06 → Bug ID appears here & on Dev Tasks
A13: QAT-011 | B13: Raj Balani | C13: Company Research | D13: Functional | E13: Execute Company Research pack — AI company brief + per-user cache | F13: See 04 / domain sheets for MOD-11 | G13: Medium | H13: Not Started | I13: 46240 | J13: 4 | K13: 0 | M13: =IFERROR(COUNTIFS('06 Bug Tracker'!N$3:N$5000,B13,'06 Bug Tracker'!L$3:L$5000,"<>Closed",'06 Bug Tracker'!L$3:L$5000,"<>Won't Fix",'06 Bug Tracker'!L$3:L$5000,"<>Duplicate"),0) | N13: Mark Fail on TC → create Bug in 06 → Bug ID appears here & on Dev Tasks
A14: QAT-012 | B14: Raj Balani | C14: Notifications & Profile | D14: Functional | E14: Execute Notifications & Profile pack — Realtime notifications, XP/streak/badges | F14: See 04 / domain sheets for MOD-12 | G14: Medium | H14: Not Started | I14: 46241 | J14: 4 | K14: 0 | M14: =IFERROR(COUNTIFS('06 Bug Tracker'!N$3:N$5000,B14,'06 Bug Tracker'!L$3:L$5000,"<>Closed",'06 Bug Tracker'!L$3:L$5000,"<>Won't Fix",'06 Bug Tracker'!L$3:L$5000,"<>Duplicate"),0) | N14: Mark Fail on TC → create Bug in 06 → Bug ID appears here & on Dev Tasks
... A32: QAT-030 | B32: Shreya Patil | C32: Cross-Cutting | D32: Retest | E32: Retest queue — bugs in Retest status (pair) | F32: bugs in Retest status (pair) | G32: Critical | H32: Not Started | I32: 46237 | J32: 3 | K32: 0 | M32: =IFERROR(COUNTIFS('06 Bug Tracker'!N$3:N$5000,B32,'06 Bug Tracker'!L$3:L$5000,"<>Closed",'06 Bug Tracker'!L$3:L$5000,"<>Won't Fix",'06 Bug Tracker'!L$3:L$5000,"<>Duplicate"),0) | N32: Update Status daily; link Bug ID when filing defects
A33: TOTAL / KPIs | J33: =SUM(J3:J32) | K33: =SUM(K3:K32) | M33: =SUM(M3:M32)
A35: Shreya open bugs (Reported By) | B35: =IFERROR(COUNTIFS('06 Bug Tracker'!N3:N5000,"Shreya Patil",'06 Bug Tracker'!L3:L5000,"<>Closed",'06 Bug Tracker'!L3:L5000,"<>Won't Fix",'06 Bug Tracker'!L3:L5000,"<>Duplicate"),0)
A36: Raj open bugs (Reported By) | B36: =IFERROR(COUNTIFS('06 Bug Tracker'!N3:N5000,"Raj Balani",'06 Bug Tracker'!L3:L5000,"<>Closed",'06 Bug Tracker'!L3:L5000,"<>Won't Fix",'06 Bug Tracker'!L3:L5000,"<>Duplicate"),0)
A37: Failed TCs (04 Pass/Fail=Fail) | B37: =IFERROR(COUNTIF('04 Test Case Repository'!P3:P5000,"Fail"),0)

Sheet QA Team
A1: QA Team Roster — Clarify AI | J1: Dashboard | K1: NAV | L1: Features | M1: Bugs | N1: Launch | O1: Smoke | P1: Creds | Q1: Env | R1: Playbooks | S1: Cases | T1: Sign-Off
A2: QA Person | B2: Role | C2: Email | D2: Capacity Hrs/Week | E2: Skills Focus | F2: Assigned Cases | G2: Est Hours Assigned | H2: Actual Hours Logged | I2: Utilization % | J2: Status | K2: Remarks
A3: Shreya Patil | B3: QA Engineer | C3: shreya.patil@clarify.ai | D3: 40 | E3: Practice Coach, Overlay, Mock Interview, Sessions/Debrief, Documents, UI/UX, Electron | F3: =COUNTIF('04 Test Case Repository'!S$3:S$5000,A3) | G3: =SUMIF('04 Test Case Repository'!S$3:S$5000,A3,'04 Test Case Repository'!T$3:T$5000) | H3: =SUMIF('04 Test Case Repository'!S$3:S$5000,A3,'04 Test Case Repository'!U$3:U$5000) | I3: =IFERROR(H3/D3,0) | J3: Active
A4: Raj Balani | B4: QA Engineer | C4: raj.balani@clarify.ai | D4: 40 | E4: Auth/Onboarding, Billing/Credits, Gov Exam Mock Tests, Admin, Prep Lab, Security, Regression | F4: =COUNTIF('04 Test Case Repository'!S$3:S$5000,A4) | G4: =SUMIF('04 Test Case Repository'!S$3:S$5000,A4,'04 Test Case Repository'!T$3:T$5000) | H4: =SUMIF('04 Test Case Repository'!S$3:S$5000,A4,'04 Test Case Repository'!U$3:U$5000) | I4: =IFERROR(H4/D4,0) | J4: Active
A5: TOTAL | D5: =SUM(D3:D4) | F5: =SUM(F3:F4) | G5: =SUM(G3:G4) | H5: =SUM(H3:H4) | I5: =IFERROR(H5/D5,0)

Sheet Dev Team
A1: Dev Team Roster — Clarify AI | J1: Dashboard | K1: NAV | L1: Features | M1: Bugs | N1: Launch | O1: Smoke | P1: Creds | Q1: Env | R1: Playbooks | S1: Cases | T1: Sign-Off
A2: Developer | B2: Role | C2: Email | D2: Capacity Hrs/Week | E2: Focus Area | F2: Open Bugs Assigned | G2: In Progress | H2: Ready for Retest | I2: Utilization Hint | J2: Status | K2: Remarks
A3: Dev Lead | B3: Engineering Lead | C3: dev.lead@clarify.ai | D3: 40 | E3: Triage, release, blockers | F3: =IFERROR(COUNTIFS('06 Bug Tracker'!M$3:M$5000,A3,'06 Bug Tracker'!L$3:L$5000,"<>Closed",'06 Bug Tracker'!L$3:L$5000,"<>Won't Fix",'06 Bug Tracker'!L$3:L$5000,"<>Duplicate"),0) | G3: =IFERROR(COUNTIFS('06 Bug Tracker'!M$3:M$5000,A3,'06 Bug Tracker'!L$3:L$5000,"In Progress"),0) | H3: =IFERROR(COUNTIFS('06 Bug Tracker'!M$3:M$5000,A3,'06 Bug Tracker'!L$3:L$5000,"Retest")+COUNTIFS('06 Bug Tracker'!M$3:M$5000,A3,'06 Bug Tracker'!L$3:L$5000,"Fixed"),0) | I3: =IF(F3>8,"Overloaded",IF(F3>4,"Busy","OK")) | J3: Active
A4: Live Coach Dev | B4: Frontend Engineer | C4: live.coach@clarify.ai | D4: 40 | E4: Practice Coach, Overlay, Mock | F4: =IFERROR(COUNTIFS('06 Bug Tracker'!M$3:M$5000,A4,'06 Bug Tracker'!L$3:L$5000,"<>Closed",'06 Bug Tracker'!L$3:L$5000,"<>Won't Fix",'06 Bug Tracker'!L$3:L$5000,"<>Duplicate"),0) | G4: =IFERROR(COUNTIFS('06 Bug Tracker'!M$3:M$5000,A4,'06 Bug Tracker'!L$3:L$5000,"In Progress"),0) | H4: =IFERROR(COUNTIFS('06 Bug Tracker'!M$3:M$5000,A4,'06 Bug Tracker'!L$3:L$5000,"Retest")+COUNTIFS('06 Bug Tracker'!M$3:M$5000,A4,'06 Bug Tracker'!L$3:L$5000,"Fixed"),0) | I4: =IF(F4>8,"Overloaded",IF(F4>4,"Busy","OK")) | J4: Active
A5: Platform Dev | B5: Full-Stack Engineer | C5: platform@clarify.ai | D5: 40 | E5: Auth, Billing, Admin, Edge | F5: =IFERROR(COUNTIFS('06 Bug Tracker'!M$3:M$5000,A5,'06 Bug Tracker'!L$3:L$5000,"<>Closed",'06 Bug Tracker'!L$3:L$5000,"<>Won't Fix",'06 Bug Tracker'!L$3:L$5000,"<>Duplicate"),0) | G5: =IFERROR(COUNTIFS('06 Bug Tracker'!M$3:M$5000,A5,'06 Bug Tracker'!L$3:L$5000,"In Progress"),0) | H5: =IFERROR(COUNTIFS('06 Bug Tracker'!M$3:M$5000,A5,'06 Bug Tracker'!L$3:L$5000,"Retest")+COUNTIFS('06 Bug Tracker'!M$3:M$5000,A5,'06 Bug Tracker'!L$3:L$5000,"Fixed"),0) | I5: =IF(F5>8,"Overloaded",IF(F5>4,"Busy","OK")) | J5: Active
A6: GovExams Dev | B6: Full-Stack Engineer | C6: govexams@clarify.ai | D6: 40 | E6: Mock tests, question bank | F6: =IFERROR(COUNTIFS('06 Bug Tracker'!M$3:M$5000,A6,'06 Bug Tracker'!L$3:L$5000,"<>Closed",'06 Bug Tracker'!L$3:L$5000,"<>Won't Fix",'06 Bug Tracker'!L$3:L$5000,"<>Duplicate"),0) | G6: =IFERROR(COUNTIFS('06 Bug Tracker'!M$3:M$5000,A6,'06 Bug Tracker'!L$3:L$5000,"In Progress"),0) | H6: =IFERROR(COUNTIFS('06 Bug Tracker'!M$3:M$5000,A6,'06 Bug Tracker'!L$3:L$5000,"Retest")+COUNTIFS('06 Bug Tracker'!M$3:M$5000,A6,'06 Bug Tracker'!L$3:L$5000,"Fixed"),0) | I6: =IF(F6>8,"Overloaded",IF(F6>4,"Busy","OK")) | J6: Active
A7: Desktop Dev | B7: Electron Engineer | C7: desktop@clarify.ai | D7: 40 | E7: Electron overlay, hotkeys | F7: =IFERROR(COUNTIFS('06 Bug Tracker'!M$3:M$5000,A7,'06 Bug Tracker'!L$3:L$5000,"<>Closed",'06 Bug Tracker'!L$3:L$5000,"<>Won't Fix",'06 Bug Tracker'!L$3:L$5000,"<>Duplicate"),0) | G7: =IFERROR(COUNTIFS('06 Bug Tracker'!M$3:M$5000,A7,'06 Bug Tracker'!L$3:L$5000,"In Progress"),0) | H7: =IFERROR(COUNTIFS('06 Bug Tracker'!M$3:M$5000,A7,'06 Bug Tracker'!L$3:L$5000,"Retest")+COUNTIFS('06 Bug Tracker'!M$3:M$5000,A7,'06 Bug Tracker'!L$3:L$5000,"Fixed"),0) | I7: =IF(F7>8,"Overloaded",IF(F7>4,"Busy","OK")) | J7: Active
A8: TOTAL | D8: =SUM(D3:D7) | F8: =SUM(F3:F7) | G8: =SUM(G3:G7) | H8: =SUM(H3:H7)

Sheet Dev Tasks
A1: Dev Tasks — live mirror of 06 Bug Tracker | J1: Dashboard | K1: NAV | L1: Features | M1: Bugs | N1: Launch | O1: Smoke | P1: Creds | Q1: Env | R1: Playbooks | S1: Cases | T1: Sign-Off
A2: Bug ID | B2: Title | C2: Module | D2: Severity | E2: Priority | F2: Bug Status | G2: Reported By (QA) | H2: Assigned Developer | I2: Needs Dev Action | J2: Dev Status | K2: Fix ETA | L2: Build Fixed | M2: Retest Owner (QA) | N2: Retest Result | O2: Dev Notes
A3: ='06 Bug Tracker'!A3 | B3: ='06 Bug Tracker'!B3 | C3: ='06 Bug Tracker'!D3 | D3: ='06 Bug Tracker'!J3 | E3: ='06 Bug Tracker'!K3 | F3: ='06 Bug Tracker'!L3 | G3: ='06 Bug Tracker'!N3 | H3: ='06 Bug Tracker'!M3 | I3: =IF(A3="","",IF(OR(F3="New",F3="Open",F3="In Progress",F3="Fixed",F3="Retest"),"Yes","No")) | J3: =IF(A3="","",IF(F3="Retest","Fixed — Ready for Retest",IF(F3="Fixed","Fixed — Ready for Retest",IF(F3="In Progress","In Progress",IF(OR(F3="New",F3="Open"),"Queued",IF(F3="Closed","Done",IF(F3="Won't Fix","Won't Fix",""))))))) | L3: ='06 Bug Tracker'!R3 | M3: ='06 Bug Tracker'!N3
A4: ='06 Bug Tracker'!A4 | B4: ='06 Bug Tracker'!B4 | C4: ='06 Bug Tracker'!D4 | D4: ='06 Bug Tracker'!J4 | E4: ='06 Bug Tracker'!K4 | F4: ='06 Bug Tracker'!L4 | G4: ='06 Bug Tracker'!N4 | H4: ='06 Bug Tracker'!M4 | I4: =IF(A4="","",IF(OR(F4="New",F4="Open",F4="In Progress",F4="Fixed",F4="Retest"),"Yes","No")) | J4: =IF(A4="","",IF(F4="Retest","Fixed — Ready for Retest",IF(F4="Fixed","Fixed — Ready for Retest",IF(F4="In Progress","In Progress",IF(OR(F4="New",F4="Open"),"Queued",IF(F4="Closed","Done",IF(F4="Won't Fix","Won't Fix",""))))))) | L4: ='06 Bug Tracker'!R4 | M4: ='06 Bug Tracker'!N4
A5: ='06 Bug Tracker'!A5 | B5: ='06 Bug Tracker'!B5 | C5: ='06 Bug Tracker'!D5 | D5: ='06 Bug Tracker'!J5 | E5: ='06 Bug Tracker'!K5 | F5: ='06 Bug Tracker'!L5 | G5: ='06 Bug Tracker'!N5 | H5: ='06 Bug Tracker'!M5 | I5: =IF(A5="","",IF(OR(F5="New",F5="Open",F5="In Progress",F5="Fixed",F5="Retest"),"Yes","No")) | J5: =IF(A5="","",IF(F5="Retest","Fixed — Ready for Retest",IF(F5="Fixed","Fixed — Ready for Retest",IF(F5="In Progress","In Progress",IF(OR(F5="New",F5="Open"),"Queued",IF(F5="Closed","Done",IF(F5="Won't Fix","Won't Fix",""))))))) | L5: ='06 Bug Tracker'!R5 | M5: ='06 Bug Tracker'!N5
A6: ='06 Bug Tracker'!A6 | B6: ='06 Bug Tracker'!B6 | C6: ='06 Bug Tracker'!D6 | D6: ='06 Bug Tracker'!J6 | E6: ='06 Bug Tracker'!K6 | F6: ='06 Bug Tracker'!L6 | G6: ='06 Bug Tracker'!N6 | H6: ='06 Bug Tracker'!M6 | I6: =IF(A6="","",IF(OR(F6="New",F6="Open",F6="In Progress",F6="Fixed",F6="Retest"),"Yes","No")) | J6: =IF(A6="","",IF(F6="Retest","Fixed — Ready for Retest",IF(F6="Fixed","Fixed — Ready for Retest",IF(F6="In Progress","In Progress",IF(OR(F6="New",F6="Open"),"Queued",IF(F6="Closed","Done",IF(F6="Won't Fix","Won't Fix",""))))))) | L6: ='06 Bug Tracker'!R6 | M6: ='06 Bug Tracker'!N6
A7: ='06 Bug Tracker'!A7 | B7: ='06 Bug Tracker'!B7 | C7: ='06 Bug Tracker'!D7 | D7: ='06 Bug Tracker'!J7 | E7: ='06 Bug Tracker'!K7 | F7: ='06 Bug Tracker'!L7 | G7: ='06 Bug Tracker'!N7 | H7: ='06 Bug Tracker'!M7 | I7: =IF(A7="","",IF(OR(F7="New",F7="Open",F7="In Progress",F7="Fixed",F7="Retest"),"Yes","No")) | J7: =IF(A7="","",IF(F7="Retest","Fixed — Ready for Retest",IF(F7="Fixed","Fixed — Ready for Retest",IF(F7="In Progress","In Progress",IF(OR(F7="New",F7="Open"),"Queued",IF(F7="Closed","Done",IF(F7="Won't Fix","Won't Fix",""))))))) | L7: ='06 Bug Tracker'!R7 | M7: ='06 Bug Tracker'!N7
A8: ='06 Bug Tracker'!A8 | B8: ='06 Bug Tracker'!B8 | C8: ='06 Bug Tracker'!D8 | D8: ='06 Bug Tracker'!J8 | E8: ='06 Bug Tracker'!K8 | F8: ='06 Bug Tracker'!L8 | G8: ='06 Bug Tracker'!N8 | H8: ='06 Bug Tracker'!M8 | I8: =IF(A8="","",IF(OR(F8="New",F8="Open",F8="In Progress",F8="Fixed",F8="Retest"),"Yes","No")) | J8: =IF(A8="","",IF(F8="Retest","Fixed — Ready for Retest",IF(F8="Fixed","Fixed — Ready for Retest",IF(F8="In Progress","In Progress",IF(OR(F8="New",F8="Open"),"Queued",IF(F8="Closed","Done",IF(F8="Won't Fix","Won't Fix",""))))))) | L8: ='06 Bug Tracker'!R8 | M8: ='06 Bug Tracker'!N8
A9: ='06 Bug Tracker'!A9 | B9: ='06 Bug Tracker'!B9 | C9: ='06 Bug Tracker'!D9 | D9: ='06 Bug Tracker'!J9 | E9: ='06 Bug Tracker'!K9 | F9: ='06 Bug Tracker'!L9 | G9: ='06 Bug Tracker'!N9 | H9: ='06 Bug Tracker'!M9 | I9: =IF(A9="","",IF(OR(F9="New",F9="Open",F9="In Progress",F9="Fixed",F9="Retest"),"Yes","No")) | J9: =IF(A9="","",IF(F9="Retest","Fixed — Ready for Retest",IF(F9="Fixed","Fixed — Ready for Retest",IF(F9="In Progress","In Progress",IF(OR(F9="New",F9="Open"),"Queued",IF(F9="Closed","Done",IF(F9="Won't Fix","Won't Fix",""))))))) | L9: ='06 Bug Tracker'!R9 | M9: ='06 Bug Tracker'!N9
A10: ='06 Bug Tracker'!A10 | B10: ='06 Bug Tracker'!B10 | C10: ='06 Bug Tracker'!D10 | D10: ='06 Bug Tracker'!J10 | E10: ='06 Bug Tracker'!K10 | F10: ='06 Bug Tracker'!L10 | G10: ='06 Bug Tracker'!N10 | H10: ='06 Bug Tracker'!M10 | I10: =IF(A10="","",IF(OR(F10="New",F10="Open",F10="In Progress",F10="Fixed",F10="Retest"),"Yes","No")) | J10: =IF(A10="","",IF(F10="Retest","Fixed — Ready for Retest",IF(F10="Fixed","Fixed — Ready for Retest",IF(F10="In Progress","In Progress",IF(OR(F10="New",F10="Open"),"Queued",IF(F10="Closed","Done",IF(F10="Won't Fix","Won't Fix",""))))))) | L10: ='06 Bug Tracker'!R10 | M10: ='06 Bug Tracker'!N10
A11: ='06 Bug Tracker'!A11 | B11: ='06 Bug Tracker'!B11 | C11: ='06 Bug Tracker'!D11 | D11: ='06 Bug Tracker'!J11 | E11: ='06 Bug Tracker'!K11 | F11: ='06 Bug Tracker'!L11 | G11: ='06 Bug Tracker'!N11 | H11: ='06 Bug Tracker'!M11 | I11: =IF(A11="","",IF(OR(F11="New",F11="Open",F11="In Progress",F11="Fixed",F11="Retest"),"Yes","No")) | J11: =IF(A11="","",IF(F11="Retest","Fixed — Ready for Retest",IF(F11="Fixed","Fixed — Ready for Retest",IF(F11="In Progress","In Progress",IF(OR(F11="New",F11="Open"),"Queued",IF(F11="Closed","Done",IF(F11="Won't Fix","Won't Fix",""))))))) | L11: ='06 Bug Tracker'!R11 | M11: ='06 Bug Tracker'!N11
A12: ='06 Bug Tracker'!A12 | B12: ='06 Bug Tracker'!B12 | C12: ='06 Bug Tracker'!D12 | D12: ='06 Bug Tracker'!J12 | E12: ='06 Bug Tracker'!K12 | F12: ='06 Bug Tracker'!L12 | G12: ='06 Bug Tracker'!N12 | H12: ='06 Bug Tracker'!M12 | I12: =IF(A12="","",IF(OR(F12="New",F12="Open",F12="In Progress",F12="Fixed",F12="Retest"),"Yes","No")) | J12: =IF(A12="","",IF(F12="Retest","Fixed — Ready for Retest",IF(F12="Fixed","Fixed — Ready for Retest",IF(F12="In Progress","In Progress",IF(OR(F12="New",F12="Open"),"Queued",IF(F12="Closed","Done",IF(F12="Won't Fix","Won't Fix",""))))))) | L12: ='06 Bug Tracker'!R12 | M12: ='06 Bug Tracker'!N12
A13: ='06 Bug Tracker'!A13 | B13: ='06 Bug Tracker'!B13 | C13: ='06 Bug Tracker'!D13 | D13: ='06 Bug Tracker'!J13 | E13: ='06 Bug Tracker'!K13 | F13: ='06 Bug Tracker'!L13 | G13: ='06 Bug Tracker'!N13 | H13: ='06 Bug Tracker'!M13 | I13: =IF(A13="","",IF(OR(F13="New",F13="Open",F13="In Progress",F13="Fixed",F13="Retest"),"Yes","No")) | J13: =IF(A13="","",IF(F13="Retest","Fixed — Ready for Retest",IF(F13="Fixed","Fixed — Ready for Retest",IF(F13="In Progress","In Progress",IF(OR(F13="New",F13="Open"),"Queued",IF(F13="Closed","Done",IF(F13="Won't Fix","Won't Fix",""))))))) | L13: ='06 Bug Tracker'!R13 | M13: ='06 Bug Tracker'!N13
A14: ='06 Bug Tracker'!A14 | B14: ='06 Bug Tracker'!B14 | C14: ='06 Bug Tracker'!D14 | D14: ='06 Bug Tracker'!J14 | E14: ='06 Bug Tracker'!K14 | F14: ='06 Bug Tracker'!L14 | G14: ='06 Bug Tracker'!N14 | H14: ='06 Bug Tracker'!M14 | I14: =IF(A14="","",IF(OR(F14="New",F14="Open",F14="In Progress",F14="Fixed",F14="Retest"),"Yes","No")) | J14: =IF(A14="","",IF(F14="Retest","Fixed — Ready for Retest",IF(F14="Fixed","Fixed — Ready for Retest",IF(F14="In Progress","In Progress",IF(OR(F14="New",F14="Open"),"Queued",IF(F14="Closed","Done",IF(F14="Won't Fix","Won't Fix",""))))))) | L14: ='06 Bug Tracker'!R14 | M14: ='06 Bug Tracker'!N14
... A152: ='06 Bug Tracker'!A152 | B152: ='06 Bug Tracker'!B152 | C152: ='06 Bug Tracker'!D152 | D152: ='06 Bug Tracker'!J152 | E152: ='06 Bug Tracker'!K152 | F152: ='06 Bug Tracker'!L152 | G152: ='06 Bug Tracker'!N152 | H152: ='06 Bug Tracker'!M152 | I152: =IF(A152="","",IF(OR(F152="New",F152="Open",F152="In Progress",F152="Fixed",F152="Retest"),"Yes","No")) | J152: =IF(A152="","",IF(F152="Retest","Fixed — Ready for Retest",IF(F152="Fixed","Fixed — Ready for Retest",IF(F152="In Progress","In Progress",IF(OR(F152="New",F152="Open"),"Queued",IF(F152="Closed","Done",IF(F152="Won't Fix","Won't Fix",""))))))) | L152: ='06 Bug Tracker'!R152 | M152: ='06 Bug Tracker'!N152
A154: QUEUE KPIs (auto)
A155: Needs Dev Action = Yes | B155: =IFERROR(COUNTIF(I3:I152,"Yes"),0)
A156: Reported by Shreya (open) | B156: =IFERROR(COUNTIFS(G3:G152,"Shreya Patil",I3:I152,"Yes"),0)
A157: Reported by Raj (open) | B157: =IFERROR(COUNTIFS(G3:G152,"Raj Balani",I3:I152,"Yes"),0)
A158: Ready for Retest | B158: =IFERROR(COUNTIF(J3:J152,"Fixed — Ready for Retest"),0)
A159: HOW TO USE | B159: 1) QA fails TC on 04 2) QA adds bug on 06 (Reported By=Shreya/Raj, Assigned To=dev) 3) Row appears here 4) Dev fixes → set Bug Status=Fixed/Retest on 06 5) QA retests → Closed

Sheet 02 Module Master
A1: Module Master — Clarify AI (20 core modules) | J1: Dashboard | K1: NAV | L1: Features | M1: Bugs | N1: Launch | O1: Smoke | P1: Creds | Q1: Env | R1: Playbooks | S1: Cases | T1: Sign-Off
A2: Module ID | B2: Module Name | C2: Portal | D2: Description | E2: Owner | F2: QA Owner | G2: Priority | H2: Status | I2: Total Features | J2: Completed Features | K2: Pending Features | L2: Est Hours | M2: Actual Hours | N2: Criticality | O2: Dependencies | P2: Remarks
A3: MOD-01 | B3: Auth & Onboarding | C3: Auth Portal | D3: Email/OAuth login, MFA, 5-step onboarding | E3: Auth Lead | F3: Raj Balani | G3: Critical | H3: In Progress | I3: 7 | J3: 6 | K3: 1 | L3: 17.5 | M3: 13.2 | N3: Critical | O3: — | P3: Seeded from audit 28 Jul 2026
A4: MOD-02 | B4: Dashboard | C4: Candidate App | D4: Home KPIs, sessions, credits, upcoming interviews | E4: Product | F4: Raj Balani | G4: High | H4: Completed | I4: 5 | J4: 5 | K4: 0 | L4: 12.5 | M4: 11 | N4: High | O4: — | P4: Seeded from audit 28 Jul 2026
A5: MOD-03 | B5: Live Practice Coach | C5: Candidate App | D5: Deepgram STT + AI hints/answers + overlay | E5: Live Coach | F5: Shreya Patil | G5: Critical | H5: Completed | I5: 9 | J5: 8 | K5: 1 | L5: 22.5 | M5: 17.6 | N5: Critical | O5: Auth, Billing credits, Deepgram | P5: Seeded from audit 28 Jul 2026
A6: MOD-04 | B6: Mock Interview | C6: Candidate App | D6: Timed mock sessions with AI scoring | E6: Live Coach | F6: Shreya Patil | G6: High | H6: In Progress | I6: 3 | J6: 1 | K6: 2 | L6: 7.5 | M6: 2.2 | N6: High | O6: Sessions, Credits | P6: Seeded from audit 28 Jul 2026
A7: MOD-05 | B7: Sessions & Debriefs | C7: Candidate App | D7: History, detail, AI debrief, scorecard share | E7: Sessions | F7: Shreya Patil | G7: High | H7: Completed | I7: 5 | J7: 5 | K7: 0 | L7: 12.5 | M7: 11 | N7: High | O7: — | P7: Seeded from audit 28 Jul 2026
A8: MOD-06 | B8: Analytics & Usage | C8: Candidate App | D8: Trends, WPM, fillers, credit usage | E8: Analytics | F8: Raj Balani | G8: Medium | H8: Completed | I8: 2 | J8: 2 | K8: 0 | L8: 5 | M8: 4.4 | N8: Medium | O8: — | P8: Seeded from audit 28 Jul 2026
A9: MOD-07 | B9: Prep Lab | C9: Candidate App | D9: STAR, rephraser, polish, company Qs | E9: Prep | F9: Raj Balani | G9: High | H9: Completed | I9: 7 | J9: 7 | K9: 0 | L9: 17.5 | M9: 15.4 | N9: High | O9: — | P9: Seeded from audit 28 Jul 2026
A10: MOD-08 | B10: Documents & Resumes | C10: Candidate App | D10: Upload, parse-resume, gap analysis, OCR | E10: Docs | F10: Shreya Patil | G10: High | H10: Completed | I10: 5 | J10: 5 | K10: 0 | L10: 12.5 | M10: 11 | N10: High | O10: Credits (parse-resume) | P10: Seeded from audit 28 Jul 2026
A11: MOD-09 | B11: Answer Bank | C11: Candidate App | D11: STAR library + AI generate via prep-tool | E11: Prep | F11: Raj Balani | G11: Medium | H11: In Progress | I11: 2 | J11: 2 | K11: 0 | L11: 5 | M11: 4.4 | N11: Medium | O11: — | P11: Seeded from audit 28 Jul 2026
A12: MOD-10 | B12: Interviews & Calendar | C12: Candidate App | D12: Manual interviews + Google Calendar sync | E12: Scheduling | F12: Raj Balani | G12: High | H12: In Progress | I12: 6 | J12: 4 | K12: 2 | L12: 15 | M12: 8.8 | N12: High | O12: — | P12: Seeded from audit 28 Jul 2026
A13: MOD-11 | B13: Company Research | C13: Candidate App | D13: AI company brief + per-user cache | E13: Prep | F13: Raj Balani | G13: Medium | H13: Completed | I13: 1 | J13: 1 | K13: 0 | L13: 2.5 | M13: 2.2 | N13: Medium | O13: — | P13: Seeded from audit 28 Jul 2026
A14: MOD-12 | B14: Notifications & Profile | C14: Candidate App | D14: Realtime notifications, XP/streak/badges | E14: Growth | F14: Raj Balani | G14: Medium | H14: In Progress | I14: 5 | J14: 4 | K14: 1 | L14: 12.5 | M14: 8.8 | N14: Medium | O14: — | P14: Seeded from audit 28 Jul 2026
... A22: MOD-20 | B22: Security & Platform | C22: All Portals | D22: RLS, webhooks, rate limits, CI, observability | E22: Platform | F22: Shreya Patil | G22: Critical | H22: In Progress | I22: 8 | J22: 4 | K22: 4 | L22: 20 | M22: 8.8 | N22: Critical | O22: — | P22: Seeded from audit 28 Jul 2026
A23: TOTAL | I23: =SUM(I3:I22) | J23: =SUM(J3:J22) | K23: =SUM(K3:K22) | L23: =SUM(L3:L22) | M23: =SUM(M3:M22)

Sheet 03 Feature Inventory
A1: Feature Inventory — full Clarify AI catalogue (114 features) | J1: Dashboard | K1: NAV | L1: ● Features | M1: Bugs | N1: Launch | O1: Smoke | P1: Creds | Q1: Env | R1: Playbooks | S1: Cases | T1: Sign-Off
A2: Feature ID | B2: Module | C2: Feature Name | D2: Description | E2: Frontend | F2: Backend | G2: Database | H2: API | I2: Edge Function | J2: Status | K2: Implementation Status | L2: QA Status | M2: Priority | N2: Risk | O2: Owner | P2: QA Owner | Q2: Est Hours | R2: Actual Hours | S2: Comments | T2: Route | U2: Deep Link | V2: How it works | W2: Role required | X2: Credit cost | Y2: Blocking bugs
A3: FEAT-001 | B3: Auth & Onboarding | C3: Email/password auth | D3: Signup/login with password | E3: Yes | F3: Yes | G3: Yes | H3: Yes | I3: N/A | J3: Completed | K3: Fully Implemented | L3: Passed | M3: Critical | N3: High | O3: Auth Lead | P3: Raj Balani | Q3: 2 | R3: 1.5 | T3: /login | U3: =IFERROR(Environments!$B$3&T3,T3) | V3: Open /login. Exercise 'Email/password auth' (Signup/login with password). Confirm happy path for intended role; note plan gates and credit toasts. | W3: Free+ | X3: 0 / N/A
A4: FEAT-002 | B4: Auth & Onboarding | C4: OAuth providers | D4: Google/GitHub/LinkedIn/Azure | E4: Yes | F4: Yes | G4: Yes | H4: Yes | I4: N/A | J4: Completed | K4: Fully Implemented | L4: In Testing | M4: Critical | N4: Medium | O4: Auth Lead | P4: Raj Balani | Q4: 3 | R4: 2 | S4: Provider enablement env-dependent | T4: /login | U4: =IFERROR(Environments!$B$3&T4,T4) | V4: Open /login. Exercise 'OAuth providers' (Google/GitHub/LinkedIn/Azure). Confirm happy path for intended role; note plan gates and credit toasts. | W4: Free+ | X4: 0 / N/A
A5: FEAT-003 | B5: Auth & Onboarding | C5: Email verification | D5: Verify email flow | E5: Yes | F5: Yes | G5: Yes | H5: Yes | I5: N/A | J5: Completed | K5: Fully Implemented | L5: Passed | M5: High | N5: Medium | O5: Auth Lead | P5: Raj Balani | Q5: 1.5 | R5: 1 | T5: /auth/verify | U5: =IFERROR(Environments!$B$3&T5,T5) | V5: Open /auth/verify. Exercise 'Email verification' (Verify email flow). Confirm happy path for intended role; note plan gates and credit toasts. | W5: Free+ | X5: 0 / N/A
A6: FEAT-004 | B6: Auth & Onboarding | C6: Password reset | D6: Forgot/reset password | E6: Yes | F6: Yes | G6: Yes | H6: Yes | I6: N/A | J6: Completed | K6: Fully Implemented | L6: Passed | M6: High | N6: Medium | O6: Auth Lead | P6: Raj Balani | Q6: 1.5 | R6: 1 | T6: /forgot-password | U6: =IFERROR(Environments!$B$3&T6,T6) | V6: Open /forgot-password. Exercise 'Password reset' (Forgot/reset password). Confirm happy path for intended role; note plan gates and credit toasts. | W6: Free+ | X6: 0 / N/A
A7: FEAT-005 | B7: Auth & Onboarding | C7: TOTP MFA | D7: Enable/verify TOTP + login challenge | E7: Yes | F7: Yes | G7: Yes | H7: Yes | I7: N/A | J7: Completed | K7: Fully Implemented | L7: Ready | M7: High | N7: High | O7: Auth Lead | P7: Raj Balani | Q7: 3 | R7: 2.5 | S7: Login AAL2 challenge wired | T7: /login | U7: =IFERROR(Environments!$B$3&T7,T7) | V7: Open /login. Exercise 'TOTP MFA' (Enable/verify TOTP + login challenge). Confirm happy path for intended role; note plan gates and credit toasts. | W7: Free+ | X7: 0 / N/A
A8: FEAT-006 | B8: Auth & Onboarding | C8: Account lockout | D8: Client lockout after failures | E8: Yes | F8: N/A | G8: N/A | H8: N/A | I8: N/A | J8: Completed | K8: Fully Implemented | L8: Not Tested | M8: Medium | N8: Medium | O8: Auth Lead | P8: Raj Balani | Q8: 1 | R8: 0 | S8: localStorage based | T8: /login | U8: =IFERROR(Environments!$B$3&T8,T8) | V8: Open /login. Exercise 'Account lockout' (Client lockout after failures). Confirm happy path for intended role; note plan gates and credit toasts. | W8: Free+ | X8: 0 / N/A
A9: FEAT-007 | B9: Auth & Onboarding | C9: Onboarding wizard 5 steps | D9: Collect profile/experience/audio/resume | E9: Yes | F9: Yes | G9: Yes | H9: Yes | I9: Yes | J9: In Progress | K9: Partial | L9: In Testing | M9: Critical | N9: High | O9: Auth Lead | P9: Shreya Patil | Q9: 5 | R9: 3 | S9: Mic+anxiety prefs now persist | T9: /login | U9: =IFERROR(Environments!$B$3&T9,T9) | V9: Open /login. Exercise 'Onboarding wizard 5 steps' (Collect profile/experience/audio/resume). Confirm happy path for intended role; note plan gates and credit toasts. | W9: Free+ | X9: 0 / N/A
A10: FEAT-008 | B10: Dashboard | C10: Home dashboard KPIs | D10: Sessions, credits, upcoming | E10: Yes | F10: Yes | G10: Yes | H10: Yes | I10: N/A | J10: Completed | K10: Fully Implemented | L10: Passed | M10: High | N10: Low | O10: Product | P10: Raj Balani | Q10: 2 | R10: 1.5 | T10: /app/dashboard | U10: =IFERROR(Environments!$B$3&T10,T10) | V10: Open /app/dashboard. Exercise 'Home dashboard KPIs' (Sessions, credits, upcoming). Confirm happy path for intended role; note plan gates and credit toasts. | W10: Free+ | X10: 0 / N/A
A11: FEAT-009 | B11: Dashboard | C11: App routing guards | D11: ProtectedRoute + admin gates | E11: Yes | F11: Yes | G11: Yes | H11: N/A | I11: N/A | J11: Completed | K11: Fully Implemented | L11: Passed | M11: Critical | N11: High | O11: Platform | P11: Shreya Patil | Q11: 2 | R11: 1.5 | T11: /app/dashboard | U11: =IFERROR(Environments!$B$3&T11,T11) | V11: Open /app/dashboard. Exercise 'App routing guards' (ProtectedRoute + admin gates). Confirm happy path for intended role; note plan gates and credit toasts. | W11: Free+ | X11: 0 / N/A
A12: FEAT-010 | B12: Dashboard | C12: In-app 404 NotFound | D12: /app/* splat catch-all | E12: Yes | F12: N/A | G12: N/A | H12: N/A | I12: N/A | J12: Completed | K12: Fully Implemented | L12: Passed | M12: Medium | N12: Low | O12: Product | P12: Raj Balani | Q12: 0.5 | R12: 0.25 | S12: P1-4 fixed | T12: /app/dashboard | U12: =IFERROR(Environments!$B$3&T12,T12) | V12: Open /app/dashboard. Exercise 'In-app 404 NotFound' (/app/* splat catch-all). Confirm happy path for intended role; note plan gates and credit toasts. | W12: Free+ | X12: 0 / N/A
A13: FEAT-011 | B13: Dashboard | C13: Mobile navigation | D13: Bottom nav destinations | E13: Yes | F13: N/A | G13: N/A | H13: N/A | I13: N/A | J13: Completed | K13: Fully Implemented | L13: Ready | M13: Medium | N13: Medium | O13: Product | P13: Raj Balani | Q13: 2 | R13: 2 | S13: Notifications/Guide/Profile/Admin in More | T13: /app/dashboard | U13: =IFERROR(Environments!$B$3&T13,T13) | V13: Mobile viewport → More sheet includes Usage and Interview Day matching sidebar. | W13: Free+ | X13: 0 / N/A
A14: FEAT-012 | B14: Dashboard | C14: Command palette | D14: Ctrl/Cmd+K search | E14: Yes | F14: N/A | G14: N/A | H14: N/A | I14: N/A | J14: Completed | K14: Partial | L14: In Testing | M14: Low | N14: Low | O14: Product | P14: Raj Balani | Q14: 1 | R14: 0.5 | S14: Nav only | T14: /app/dashboard | U14: =IFERROR(Environments!$B$3&T14,T14) | V14: Open /app/dashboard. Exercise 'Command palette' (Ctrl/Cmd+K search). Confirm happy path for intended role; note plan gates and credit toasts. | W14: Free+ | X14: 0 / N/A
A15: FEAT-013 | B15: Live Practice Coach | C15: Live Practice Coach session | D15: Core live rehearsal loop | E15: Yes | F15: Yes | G15: Yes | H15: Yes | I15: Yes | J15: Completed | K15: Fully Implemented | L15: Passed | M15: Critical | N15: Critical | O15: Live Coach | P15: Shreya Patil | Q15: 8 | R15: 6 | T15: /app/live | U15: =IFERROR(Environments!$B$3&T15,T15) | V15: Open /app/live. Exercise 'Live Practice Coach session' (Core live rehearsal loop). Confirm happy path for intended role; note plan gates and credit toasts. | W15: Free+ | X15: 0 / N/A
A16: FEAT-014 | B16: Live Practice Coach | C16: System/tab audio capture | D16: Chrome/Edge tab audio | E16: Yes | F16: N/A | G16: N/A | H16: N/A | I16: N/A | J16: Completed | K16: Fully Implemented | L16: Passed | M16: Critical | N16: High | O16: Live Coach | P16: Shreya Patil | Q16: 3 | R16: 2 | S16: Chrome/Edge only | T16: /app/live | U16: =IFERROR(Environments!$B$3&T16,T16) | V16: Open /app/live. Exercise 'System/tab audio capture' (Chrome/Edge tab audio). Confirm happy path for intended role; note plan gates and credit toasts. | W16: Free+ | X16: 0 / N/A
A17: FEAT-015 | B17: Live Practice Coach | C17: Deepgram streaming STT | D17: nova-2-meeting stream | E17: Yes | F17: Yes | G17: N/A | H17: Yes | I17: Yes | J17: Completed | K17: Fully Implemented | L17: Passed | M17: Critical | N17: Critical | O17: Live Coach | P17: Shreya Patil | Q17: 4 | R17: 3.5 | S17: deepgram-token | T17: /app/live | U17: =IFERROR(Environments!$B$3&T17,T17) | V17: Open /app/live. Exercise 'Deepgram streaming STT' (nova-2-meeting stream). Confirm happy path for intended role; note plan gates and credit toasts. | W17: Free+ | X17: 0 / N/A
A18: FEAT-016 | B18: Live Practice Coach | C18: Speaker diarization | D18: Interviewer vs candidate | E18: Yes | F18: Yes | G18: Yes | H18: N/A | I18: N/A | J18: Completed | K18: Fully Implemented | L18: Passed | M18: High | N18: High | O18: Live Coach | P18: Shreya Patil | Q18: 3 | R18: 2 | T18: /app/live | U18: =IFERROR(Environments!$B$3&T18,T18) | V18: Open /app/live. Exercise 'Speaker diarization' (Interviewer vs candidate). Confirm happy path for intended role; note plan gates and credit toasts. | W18: Free+ | X18: 0 / N/A
A19: FEAT-017 | B19: Live Practice Coach | C19: Real-time AI hints | D19: generate-hint | E19: Yes | F19: Yes | G19: Yes | H19: Yes | I19: Yes | J19: Completed | K19: Fully Implemented | L19: In Testing | M19: Critical | N19: High | O19: Live Coach | P19: Shreya Patil | Q19: 3 | R19: 2 | S19: Credits | T19: /app/live | U19: =IFERROR(Environments!$B$3&T19,T19) | V19: Open /app/live. Exercise 'Real-time AI hints' (generate-hint). Confirm happy path for intended role; note plan gates and credit toasts. | W19: Free+ | X19: 2 (live_hint)
A20: FEAT-018 | B20: Live Practice Coach | C20: Streaming AI answers | D20: generate-answer SSE | E20: Yes | F20: Yes | G20: Yes | H20: Yes | I20: Yes | J20: Completed | K20: Fully Implemented | L20: In Testing | M20: Critical | N20: Critical | O20: Live Coach | P20: Shreya Patil | Q20: 5 | R20: 4 | S20: Free limited; overlay Pro | T20: /app/live | U20: =IFERROR(Environments!$B$3&T20,T20) | V20: Open /app/live. Exercise 'Streaming AI answers' (generate-answer SSE). Confirm happy path for intended role; note plan gates and credit toasts. | W20: Free+ | X20: 8 (live_answer)
A21: FEAT-019 | B21: Live Practice Coach | C21: Screenshot/vision capture | D21: Coding problem OCR/vision | E21: Yes | F21: Yes | G21: N/A | H21: Yes | I21: Yes | J21: Completed | K21: Fully Implemented | L21: In Testing | M21: High | N21: High | O21: Live Coach | P21: Shreya Patil | Q21: 4 | R21: 2 | S21: Pro gated | T21: /app/live | U21: =IFERROR(Environments!$B$3&T21,T21) | V21: Open /app/live. Exercise 'Screenshot/vision capture' (Coding problem OCR/vision). Confirm happy path for intended role; note plan gates and credit toasts. | W21: Pro+ | X21: 10 (screenshot_answer)
A22: FEAT-020 | B22: Live Practice Coach | C22: Stealth mode | D22: UI labels only | E22: Yes | F22: N/A | G22: N/A | H22: N/A | I22: N/A | J22: In Progress | K22: Partial | L22: Failed | M22: Medium | N22: Medium | O22: Desktop | P22: Shreya Patil | Q22: 2 | R22: 0.5 | S22: No capture evasion | T22: /app/live | U22: =IFERROR(Environments!$B$3&T22,T22) | V22: Open /app/live. Exercise 'Stealth mode' (UI labels only). Confirm happy path for intended role; note plan gates and credit toasts. | W22: Free+ | X22: 0 / N/A
A23: FEAT-021 | B23: Live Practice Coach | C23: Panic mode | D23: Static coaching steps | E23: Yes | F23: N/A | G23: N/A | H23: N/A | I23: N/A | J23: Completed | K23: Fully Implemented | L23: Passed | M23: Medium | N23: Low | O23: Live Coach | P23: Shreya Patil | Q23: 1 | R23: 0.5 | T23: /app/live | U23: =IFERROR(Environments!$B$3&T23,T23) | V23: Open /app/live. Exercise 'Panic mode' (Static coaching steps). Confirm happy path for intended role; note plan gates and credit toasts. | W23: Free+ | X23: 0 / N/A
A24: FEAT-022 | B24: Mock Interview | C24: Mock interview session | D24: Timed AI mock | E24: Yes | F24: Yes | G24: Yes | H24: Yes | I24: Yes | J24: In Progress | K24: Partial | L24: In Testing | M24: High | N24: High | O24: Live Coach | P24: Shreya Patil | Q24: 6 | R24: 3 | S24: No TTS | T24: /app/mock | U24: =IFERROR(Environments!$B$3&T24,T24) | V24: Open /app/mock. Exercise 'Mock interview session' (Timed AI mock). Confirm happy path for intended role; note plan gates and credit toasts. | W24: Free+ | X24: 0 / N/A
A25: FEAT-023 | B25: Mock Interview | C25: Mock warm-up | D25: Warm-up questions | E25: Yes | F25: N/A | G25: N/A | H25: N/A | I25: N/A | J25: Completed | K25: Partial | L25: Passed | M25: Medium | N25: Low | O25: Live Coach | P25: Shreya Patil | Q25: 1.5 | R25: 1 | S25: WARMUP_MAX copy fixed | T25: /app/mock | U25: =IFERROR(Environments!$B$3&T25,T25) | V25: Open /app/mock. Exercise 'Mock warm-up' (Warm-up questions). Confirm happy path for intended role; note plan gates and credit toasts. | W25: Free+ | X25: 0 / N/A
A26: FEAT-024 | B26: Mock Interview | C26: Mock TTS playback | D26: Spoken questions | E26: No | F26: No | G26: N/A | H26: No | I26: No | J26: Not Started | K26: Not Built | L26: Not Tested | M26: High | N26: Medium | O26: Live Coach | P26: Shreya Patil | Q26: 8 | R26: 0 | S26: Roadmap | T26: /app/mock | U26: =IFERROR(Environments!$B$3&T26,T26) | V26: Open /app/mock. Exercise 'Mock TTS playback' (Spoken questions). Confirm happy path for intended role; note plan gates and credit toasts. | W26: Free+ | X26: 0 / N/A | Y26: BUG-OPEN-04
A27: FEAT-025 | B27: Sessions & Debriefs | C27: Session history list | D27: Past sessions | E27: Yes | F27: Yes | G27: Yes | H27: Yes | I27: N/A | J27: Completed | K27: Fully Implemented | L27: Passed | M27: High | N27: Low | O27: Sessions | P27: Shreya Patil | Q27: 2 | R27: 1.5 | T27: /app/sessions | U27: =IFERROR(Environments!$B$3&T27,T27) | V27: Open /app/sessions. Exercise 'Session history list' (Past sessions). Confirm happy path for intended role; note plan gates and credit toasts. | W27: Free+ | X27: 0 / N/A
A28: FEAT-026 | B28: Sessions & Debriefs | C28: Session detail scores | D28: Dimension breakdown | E28: Yes | F28: Yes | G28: Yes | H28: N/A | I28: N/A | J28: Completed | K28: Fully Implemented | L28: Passed | M28: High | N28: Medium | O28: Sessions | P28: Shreya Patil | Q28: 2 | R28: 1.5 | S28: Null=Not scored P1-7 | T28: /app/sessions | U28: =IFERROR(Environments!$B$3&T28,T28) | V28: Open /app/sessions. Exercise 'Session detail scores' (Dimension breakdown). Confirm happy path for intended role; note plan gates and credit toasts. | W28: Free+ | X28: 0 / N/A
A29: FEAT-027 | B29: Sessions & Debriefs | C29: AI Debrief | D29: generate-debrief | E29: Yes | F29: Yes | G29: Yes | H29: Yes | I29: Yes | J29: Completed | K29: Fully Implemented | L29: Passed | M29: High | N29: Medium | O29: Sessions | P29: Shreya Patil | Q29: 3 | R29: 2 | T29: /app/sessions | U29: =IFERROR(Environments!$B$3&T29,T29) | V29: Open /app/sessions. Exercise 'AI Debrief' (generate-debrief). Confirm happy path for intended role; note plan gates and credit toasts. | W29: Free+ | X29: 15 (session_debrief)
A30: FEAT-028 | B30: Sessions & Debriefs | C30: Debrief public share | D30: Share token link | E30: Yes | F30: Yes | G30: Yes | H30: Yes | I30: N/A | J30: Completed | K30: Fully Implemented | L30: In Testing | M30: Medium | N30: Low | O30: Sessions | P30: Shreya Patil | Q30: 2 | R30: 1 | T30: /app/sessions | U30: =IFERROR(Environments!$B$3&T30,T30) | V30: Open /app/sessions. Exercise 'Debrief public share' (Share token link). Confirm happy path for intended role; note plan gates and credit toasts. | W30: Free+ | X30: 0 / N/A
A31: FEAT-029 | B31: Sessions & Debriefs | C31: Scorecard | D31: Client Gemini scoring | E31: Yes | F31: Yes | G31: Yes | H31: Yes | I31: Partial | J31: Completed | K31: Fully Implemented | L31: In Testing | M31: High | N31: Medium | O31: Sessions | P31: Shreya Patil | Q31: 3 | R31: 1.5 | T31: /app/sessions | U31: =IFERROR(Environments!$B$3&T31,T31) | V31: Open /app/sessions. Exercise 'Scorecard' (Client Gemini scoring). Confirm happy path for intended role; note plan gates and credit toasts. | W31: Free+ | X31: 0 / N/A
A32: FEAT-030 | B32: Analytics & Usage | C32: Analytics dashboard | D32: Trends WPM fillers | E32: Yes | F32: Yes | G32: Yes | H32: Yes | I32: Yes | J32: Completed | K32: Fully Implemented | L32: Passed | M32: Medium | N32: Low | O32: Analytics | P32: Raj Balani | Q32: 3 | R32: 2 | S32: total_sessions fix P2-8 | T32: /app/analytics | U32: =IFERROR(Environments!$B$3&T32,T32) | V32: Open /app/analytics. Exercise 'Analytics dashboard' (Trends WPM fillers). Confirm happy path for intended role; note plan gates and credit toasts. | W32: Free+ | X32: 0 / N/A
A33: FEAT-031 | B33: Analytics & Usage | C33: Credits usage dashboard | D33: Ledger view | E33: Yes | F33: Yes | G33: Yes | H33: Yes | I33: N/A | J33: Completed | K33: Fully Implemented | L33: Passed | M33: High | N33: Medium | O33: Billing | P33: Raj Balani | Q33: 2 | R33: 1.5 | T33: /app/usage | U33: =IFERROR(Environments!$B$3&T33,T33) | V33: Open /app/usage. Exercise 'Credits usage dashboard' (Ledger view). Confirm happy path for intended role; note plan gates and credit toasts. | W33: Free+ | X33: 0 / N/A
A34: FEAT-032 | B34: Prep Lab | C34: Prep Lab hub | D34: Tool launcher | E34: Yes | F34: Yes | G34: N/A | H34: Yes | I34: Yes | J34: Completed | K34: Fully Implemented | L34: Passed | M34: High | N34: Low | O34: Prep | P34: Raj Balani | Q34: 1 | R34: 0.5 | T34: /app/prep | U34: =IFERROR(Environments!$B$3&T34,T34) | V34: Open /app/prep. Exercise 'Prep Lab hub' (Tool launcher). Confirm happy path for intended role; note plan gates and credit toasts. | W34: Free+ | X34: 0 / N/A
A35: FEAT-033 | B35: Prep Lab | C35: STAR Builder | D35: STAR answer builder | E35: Yes | F35: Yes | G35: Yes | H35: Yes | I35: Yes | J35: Completed | K35: Fully Implemented | L35: Passed | M35: High | N35: Medium | O35: Prep | P35: Raj Balani | Q35: 3 | R35: 2 | S35: Cost from economics | T35: /app/prep | U35: =IFERROR(Environments!$B$3&T35,T35) | V35: Open /app/prep. Exercise 'STAR Builder' (STAR answer builder). Confirm happy path for intended role; note plan gates and credit toasts. | W35: Free+ | X35: 10 (star_builder)
A36: FEAT-034 | B36: Prep Lab | C36: Project Builder | D36: Project drafts | E36: Yes | F36: Partial | G36: N/A | H36: Yes | I36: Yes | J36: Completed | K36: Fully Implemented | L36: In Testing | M36: Medium | N36: Low | O36: Prep | P36: Raj Balani | Q36: 2 | R36: 1 | S36: localStorage drafts | T36: /app/prep | U36: =IFERROR(Environments!$B$3&T36,T36) | V36: Open /app/prep. Exercise 'Project Builder' (Project drafts). Confirm happy path for intended role; note plan gates and credit toasts. | W36: Free+ | X36: 0 / N/A
A37: FEAT-035 | B37: Prep Lab | C37: Rephraser | D37: Rewrite answers | E37: Yes | F37: Yes | G37: N/A | H37: Yes | I37: Yes | J37: Completed | K37: Fully Implemented | L37: Passed | M37: Medium | N37: Low | O37: Prep | P37: Raj Balani | Q37: 2 | R37: 1.5 | S37: Error state wired | T37: /app/prep | U37: =IFERROR(Environments!$B$3&T37,T37) | V37: Open /app/prep. Exercise 'Rephraser' (Rewrite answers). Confirm happy path for intended role; note plan gates and credit toasts. | W37: Free+ | X37: 3 (rephraser)
A38: FEAT-036 | B38: Prep Lab | C38: Coding Hints catalog | D38: DB coding hints | E38: Yes | F38: Yes | G38: Yes | H38: Yes | I38: N/A | J38: Completed | K38: Fully Implemented | L38: In Testing | M38: Medium | N38: Low | O38: Prep | P38: Raj Balani | Q38: 2 | R38: 1 | T38: /app/prep | U38: =IFERROR(Environments!$B$3&T38,T38) | V38: Open /app/prep. Exercise 'Coding Hints catalog' (DB coding hints). Confirm happy path for intended role; note plan gates and credit toasts. | W38: Free+ | X38: 0 / N/A
A39: FEAT-037 | B39: Prep Lab | C39: System Design topics | D39: DB topics | E39: Yes | F39: Yes | G39: Yes | H39: Yes | I39: N/A | J39: Completed | K39: Fully Implemented | L39: In Testing | M39: Medium | N39: Low | O39: Prep | P39: Raj Balani | Q39: 2 | R39: 1 | T39: /app/prep | U39: =IFERROR(Environments!$B$3&T39,T39) | V39: Open /app/prep. Exercise 'System Design topics' (DB topics). Confirm happy path for intended role; note plan gates and credit toasts. | W39: Free+ | X39: 0 / N/A
A40: FEAT-038 | B40: Prep Lab | C40: prep-tool AI suite | D40: 12 AI prep tools | E40: Yes | F40: Yes | G40: Yes | H40: Yes | I40: Yes | J40: Completed | K40: Fully Implemented | L40: In Testing | M40: High | N40: Medium | O40: Prep | P40: Raj Balani | Q40: 4 | R40: 2 | T40: /app/prep | U40: =IFERROR(Environments!$B$3&T40,T40) | V40: Open /app/prep. Exercise 'prep-tool AI suite' (12 AI prep tools). Confirm happy path for intended role; note plan gates and credit toasts. | W40: Free+ | X40: 0 / N/A
...

Sheet 04 Test Case Repository
