Workbook

Sheet 00 Cover & Instructions
A1: Clarify AI — Black-Box Manual QA Workbook
A2: CYCLE 31 AUG 2026 | COMPLETE WITHIN 2 DAYS | 3 TESTERS PRE-ASSIGNED | UPDATE PEACH COLUMNS ONLY
A4: ⚠ CONFIDENTIAL — This workbook contains QA test account passwords for closed-beta testers only. Do not forward outside the QA team. Do not commit to a public repo.
A6: CYCLE
A7: Wave 2 — Retest after 30-08 remediation + live Gov exam proof.
A8: Window: complete within 2 days (31 Aug – 1 Sep 2026, IST). Testers pick their own hours.
A9: App: https://clarify.ai.sltfinanceindia.com
A11: TEAM (3 testers — every case is pre-assigned)
A12: 1. Anushka — Government Exams + live proof, AI Fallback, Practice Coach, Live Overlay, Mock Interview, Documents, Resume/JD, AI Chat, Module smoke, Journey 2, Admin gov ingest/review (TC-ADM-019–024)
A13: 2. Sultana — Billing, Credits, Dashboard, Prep Lab, Sessions, Reports, Analytics, Answer Bank, Learning/Community/Coding, Admin (non-gov), API, Regression, Journeys 1 and 4–5
A14: 3. Venkat — Authentication, Onboarding, Security, Public pages, Settings, Integrations, Scheduler, Accessibility, Responsive / Cross-Browser
A16: ENGINEERING STATUS (as of 31 Aug 2026) — NOT LIVE-PROVEN
... A59: RELEASE: Stay RELEASE BLOCKED until 00d TC-GOV-LIVE-06 (or Full Mock equivalent) produces a real completed paper on the live URL.

Sheet 00a Execution Window
A1: 00a — Execution Window (2 days)
A2: Complete within 2 days (31 Aug – 1 Sep 2026, IST). One row per tester. No day-by-day calendar and no time slots. Update Status as you go. Testers choose their own hours.
A4: Tester | B4: Assigned sheets / work | C4: Window | D4: Cycle start | E4: Cycle end | F4: Location / URL | G4: Status | H4: Section Gate Link | I4: Notes / blockers | J4: Updated By | K4: Updated At
A5: Anushka | B5: 05 Module Smoke; 10 Practice Coach; 11 Live Copilot; 12 Mock Interview; 13 Government Exams; 00d Live Gov Exam Proof; 14 AI Coach; 16 Documents; 17 Resume/JD; 36 AI Fallback; Admin gov TC-ADM-019–024; Journey 2; 00c Gov remediations | C5: Complete within 2 days (31 Aug – 1 Sep 2026, IST) | D5: 2026-08-31 | E5: 2026-09-01 | F5: https://clarify.ai.sltfinanceindia.com | G5: Not Started | H5: See 00b Section Completion Gate
A6: Sultana | B6: 09 Dashboard; 15 Prep Lab; 18 Answer Bank; 20 Sessions; 21 Reports; 22 Analytics; 23 Billing; 24 Credits; 26 Notifications; 28–30 Learning/Community/Coding; 31 Admin (non-gov); 35 API; 37 Regression; Journeys 1, 4–5; 00c credits/sessions remediations | C6: Complete within 2 days (31 Aug – 1 Sep 2026, IST) | D6: 2026-08-31 | E6: 2026-09-01 | F6: https://clarify.ai.sltfinanceindia.com | G6: Not Started | H6: See 00b Section Completion Gate
A7: Venkat | B7: 06 Public Pages; 07 Authentication; 08 Onboarding; 19 Scheduler; 25 Settings; 27 Integrations; 32 Security; 33 Accessibility; 34 Responsive; 00c auth/public/settings remediations | C7: Complete within 2 days (31 Aug – 1 Sep 2026, IST) | D7: 2026-08-31 | E7: 2026-09-01 | F7: https://clarify.ai.sltfinanceindia.com | G7: Not Started | H7: See 00b Section Completion Gate
A10: Testers | C10: Rule
A11: 1. Anushka | C11: P0/P1 first. P2+ if time remains in the same 2-day window.
A12: 2. Sultana
A13: 3. Venkat

Sheet 00b Section Completion Gate
A1: 00b — Section Completion Gate
A2: RULE: Set Section Status to 'ALL FILLED — READY TO CLOSE' ONLY when Ready? = YES. Ready? becomes YES when (a) every test case Pass/Fail is not 'Not Run' and (b) every Actual Result cell is non-empty. Do not close early.
A4: Sheet | B4: Assigned Tester | C4: Total Cases | D4: Not Run (count) | E4: Blank Actual (count) | F4: Ready? | G4: Section Status (select) | H4: Closed By | I4: Closed Date | J4: Notes
A5: 00d Live Gov Exam Proof | B5: Anushka | C5: 24 | D5: =COUNTIF('00d Live Gov Exam Proof'!U5:U28,"Not Run") | E5: =COUNTBLANK('00d Live Gov Exam Proof'!T5:T28) | F5: =IF(AND(D5=0,E5=0),"YES","NO") | G5: Not Started
A6: 05 Module Test Cases | B6: Anushka | C6: 22 | D6: =COUNTIF('05 Module Test Cases'!U5:U26,"Not Run") | E6: =COUNTBLANK('05 Module Test Cases'!T5:T26) | F6: =IF(AND(D6=0,E6=0),"YES","NO") | G6: Not Started
A7: 06 Public Pages | B7: Venkat | C7: 15 | D7: =COUNTIF('06 Public Pages'!U5:U19,"Not Run") | E7: =COUNTBLANK('06 Public Pages'!T5:T19) | F7: =IF(AND(D7=0,E7=0),"YES","NO") | G7: Not Started
A8: 07 Authentication | B8: Venkat | C8: 16 | D8: =COUNTIF('07 Authentication'!U5:U20,"Not Run") | E8: =COUNTBLANK('07 Authentication'!T5:T20) | F8: =IF(AND(D8=0,E8=0),"YES","NO") | G8: Not Started
A9: 08 Onboarding | B9: Venkat | C9: 8 | D9: =COUNTIF('08 Onboarding'!U5:U12,"Not Run") | E9: =COUNTBLANK('08 Onboarding'!T5:T12) | F9: =IF(AND(D9=0,E9=0),"YES","NO") | G9: Not Started
A10: 09 Dashboard | B10: Sultana | C10: 8 | D10: =COUNTIF('09 Dashboard'!U5:U12,"Not Run") | E10: =COUNTBLANK('09 Dashboard'!T5:T12) | F10: =IF(AND(D10=0,E10=0),"YES","NO") | G10: Not Started
A11: 10 Practice Coach | B11: Anushka | C11: 16 | D11: =COUNTIF('10 Practice Coach'!U5:U20,"Not Run") | E11: =COUNTBLANK('10 Practice Coach'!T5:T20) | F11: =IF(AND(D11=0,E11=0),"YES","NO") | G11: Not Started
A12: 11 Live Copilot | B12: Anushka | C12: 5 | D12: =COUNTIF('11 Live Copilot'!U5:U9,"Not Run") | E12: =COUNTBLANK('11 Live Copilot'!T5:T9) | F12: =IF(AND(D12=0,E12=0),"YES","NO") | G12: Not Started
A13: 12 Mock Interview | B13: Anushka | C13: 10 | D13: =COUNTIF('12 Mock Interview'!U5:U14,"Not Run") | E13: =COUNTBLANK('12 Mock Interview'!T5:T14) | F13: =IF(AND(D13=0,E13=0),"YES","NO") | G13: Not Started
A14: 13 Government Exams | B14: Anushka | C14: 25 | D14: =COUNTIF('13 Government Exams'!U5:U29,"Not Run") | E14: =COUNTBLANK('13 Government Exams'!T5:T29) | F14: =IF(AND(D14=0,E14=0),"YES","NO") | G14: Not Started
A15: 14 AI Coach Chatbot | B15: Anushka | C15: 8 | D15: =COUNTIF('14 AI Coach Chatbot'!U5:U12,"Not Run") | E15: =COUNTBLANK('14 AI Coach Chatbot'!T5:T12) | F15: =IF(AND(D15=0,E15=0),"YES","NO") | G15: Not Started
A16: 15 Prep Lab | B16: Sultana | C16: 8 | D16: =COUNTIF('15 Prep Lab'!U5:U12,"Not Run") | E16: =COUNTBLANK('15 Prep Lab'!T5:T12) | F16: =IF(AND(D16=0,E16=0),"YES","NO") | G16: Not Started
A17: 16 Documents | B17: Anushka | C17: 10 | D17: =COUNTIF('16 Documents'!U5:U14,"Not Run") | E17: =COUNTBLANK('16 Documents'!T5:T14) | F17: =IF(AND(D17=0,E17=0),"YES","NO") | G17: Not Started
A18: 17 Resume JD Parsing | B18: Anushka | C18: 4 | D18: =COUNTIF('17 Resume JD Parsing'!U5:U8,"Not Run") | E18: =COUNTBLANK('17 Resume JD Parsing'!T5:T8) | F18: =IF(AND(D18=0,E18=0),"YES","NO") | G18: Not Started
A19: 18 Answer Bank | B19: Sultana | C19: 6 | D19: =COUNTIF('18 Answer Bank'!U5:U10,"Not Run") | E19: =COUNTBLANK('18 Answer Bank'!T5:T10) | F19: =IF(AND(D19=0,E19=0),"YES","NO") | G19: Not Started
A20: 19 Interview Scheduler | B20: Venkat | C20: 5 | D20: =COUNTIF('19 Interview Scheduler'!U5:U9,"Not Run") | E20: =COUNTBLANK('19 Interview Scheduler'!T5:T9) | F20: =IF(AND(D20=0,E20=0),"YES","NO") | G20: Not Started
A21: 20 Sessions | B21: Sultana | C21: 5 | D21: =COUNTIF('20 Sessions'!U5:U9,"Not Run") | E21: =COUNTBLANK('20 Sessions'!T5:T9) | F21: =IF(AND(D21=0,E21=0),"YES","NO") | G21: Not Started
A22: 21 Reports | B22: Sultana | C22: 5 | D22: =COUNTIF('21 Reports'!U5:U9,"Not Run") | E22: =COUNTBLANK('21 Reports'!T5:T9) | F22: =IF(AND(D22=0,E22=0),"YES","NO") | G22: Not Started
A23: 22 Analytics | B23: Sultana | C23: 4 | D23: =COUNTIF('22 Analytics'!U5:U8,"Not Run") | E23: =COUNTBLANK('22 Analytics'!T5:T8) | F23: =IF(AND(D23=0,E23=0),"YES","NO") | G23: Not Started
A24: 23 Billing | B24: Sultana | C24: 8 | D24: =COUNTIF('23 Billing'!U5:U12,"Not Run") | E24: =COUNTBLANK('23 Billing'!T5:T12) | F24: =IF(AND(D24=0,E24=0),"YES","NO") | G24: Not Started
A25: 24 Credits | B25: Sultana | C25: 6 | D25: =COUNTIF('24 Credits'!U5:U10,"Not Run") | E25: =COUNTBLANK('24 Credits'!T5:T10) | F25: =IF(AND(D25=0,E25=0),"YES","NO") | G25: Not Started
A26: 25 Settings | B26: Venkat | C26: 15 | D26: =COUNTIF('25 Settings'!U5:U19,"Not Run") | E26: =COUNTBLANK('25 Settings'!T5:T19) | F26: =IF(AND(D26=0,E26=0),"YES","NO") | G26: Not Started
A27: 26 Notifications | B27: Sultana | C27: 4 | D27: =COUNTIF('26 Notifications'!U5:U8,"Not Run") | E27: =COUNTBLANK('26 Notifications'!T5:T8) | F27: =IF(AND(D27=0,E27=0),"YES","NO") | G27: Not Started
A28: 27 Integrations | B28: Venkat | C28: 5 | D28: =COUNTIF('27 Integrations'!U5:U9,"Not Run") | E28: =COUNTBLANK('27 Integrations'!T5:T9) | F28: =IF(AND(D28=0,E28=0),"YES","NO") | G28: Not Started
A29: 28 Learning Hub | B29: Sultana | C29: 3 | D29: =COUNTIF('28 Learning Hub'!U5:U7,"Not Run") | E29: =COUNTBLANK('28 Learning Hub'!T5:T7) | F29: =IF(AND(D29=0,E29=0),"YES","NO") | G29: Not Started
A30: 29 Community | B30: Sultana | C30: 4 | D30: =COUNTIF('29 Community'!U5:U8,"Not Run") | E30: =COUNTBLANK('29 Community'!T5:T8) | F30: =IF(AND(D30=0,E30=0),"YES","NO") | G30: Not Started
A31: 30 Coding Lab | B31: Sultana | C31: 5 | D31: =COUNTIF('30 Coding Lab'!U5:U9,"Not Run") | E31: =COUNTBLANK('30 Coding Lab'!T5:T9) | F31: =IF(AND(D31=0,E31=0),"YES","NO") | G31: Not Started
A32: 31 Admin Portal | B32: Sultana | C32: 28 | D32: =COUNTIF('31 Admin Portal'!U5:U32,"Not Run") | E32: =COUNTBLANK('31 Admin Portal'!T5:T32) | F32: =IF(AND(D32=0,E32=0),"YES","NO") | G32: Not Started
A33: 32 Security | B33: Venkat | C33: 6 | D33: =COUNTIF('32 Security'!U5:U10,"Not Run") | E33: =COUNTBLANK('32 Security'!T5:T10) | F33: =IF(AND(D33=0,E33=0),"YES","NO") | G33: Not Started
A34: 33 Accessibility | B34: Venkat | C34: 5 | D34: =COUNTIF('33 Accessibility'!U5:U9,"Not Run") | E34: =COUNTBLANK('33 Accessibility'!T5:T9) | F34: =IF(AND(D34=0,E34=0),"YES","NO") | G34: Not Started
A35: 34 Responsive Cross-Browser | B35: Venkat | C35: 11 | D35: =COUNTIF('34 Responsive Cross-Browser'!U5:U15,"Not Run") | E35: =COUNTBLANK('34 Responsive Cross-Browser'!T5:T15) | F35: =IF(AND(D35=0,E35=0),"YES","NO") | G35: Not Started
A36: 35 API Network Observation | B36: Sultana | C36: 6 | D36: =COUNTIF('35 API Network Observation'!U5:U10,"Not Run") | E36: =COUNTBLANK('35 API Network Observation'!T5:T10) | F36: =IF(AND(D36=0,E36=0),"YES","NO") | G36: Not Started
A37: 36 AI Fallback | B37: Anushka | C37: 5 | D37: =COUNTIF('36 AI Fallback'!U5:U9,"Not Run") | E37: =COUNTBLANK('36 AI Fallback'!T5:T9) | F37: =IF(AND(D37=0,E37=0),"YES","NO") | G37: Not Started
A38: 37 Regression | B38: Sultana | C38: 15 | D38: =COUNTIF('37 Regression'!U5:U19,"Not Run") | E38: =COUNTBLANK('37 Regression'!T5:T19) | F38: =IF(AND(D38=0,E38=0),"YES","NO") | G38: Not Started
A39: 38 Cross-Module Journeys | B39: Sultana | C39: 5 | D39: =COUNTIF('38 Cross-Module Journeys'!U5:U9,"Not Run") | E39: =COUNTBLANK('38 Cross-Module Journeys'!T5:T9) | F39: =IF(AND(D39=0,E39=0),"YES","NO") | G39: Not Started
A41: TEAM ROLL-UP
A42: Sections Ready (YES count) | B42: =COUNTIF(F5:F39,"YES")
...

Sheet 00c Retest Wave
A1: 00c — Retest Wave (31 Aug 2026)
A2: Retest engineering remediations from qa-evidence/30-08-2026-remediation.md. Opening a page is NOT Pass. Undeployed backend = Blocked + blocker code, not Fail.
A4: Test Case ID | B4: Module | C4: Tester | D4: Priority | E4: Previous result (if known) | F4: Fix claimed by eng | G4: Live proof required? | H4: Runnable now? (Yes / Blocked) | I4: Blocker | J4: Pass / Fail | K4: Actual Result | L4: Defect ID | M4: Evidence | N4: Notes
A5: TC-GOV-007 | B5: Government Exams | C5: Anushka | D5: P0 | E5: Fail / Blocked (poll + charge-before-paper) | F5: JOB_POLL backoff; reserve credits until paper exists | G5: Yes | H5: Blocked | I5: BLK-EDGE / BLK-PY / BLK-MIG until live paper exists | J5: Not Run | N5: Full Mock generate. If 404/timeout mark Blocked not Fail.
A6: TC-GOV-008 | B6: Government Exams | C6: Anushka | D6: P0 | E6: Fail / Blocked | F6: Custom Practice via unified factory; count not Full Mock clamp | G6: Yes — P0 release gate | H6: Blocked | I6: BLK-EDGE / BLK-PY / BLK-MIG | J6: Not Run | N6: Must produce a completed Custom Practice paper for GO.
A7: TC-GOV-010 | B7: Government Exams | C7: Anushka | D7: P0 | E7: Fail (refresh trap / bootstrap) | F7: Gov browse during recovery; truthful restore after refresh | G7: Yes | H7: Yes (hub/search); generate path maybe Blocked | I7: BLK-EDGE if still Generating forever | J7: Not Run | N7: DEF-013 / bootstrap: hub must not infinite-search.
A8: TC-GOV-011 | B8: Government Exams | C8: Anushka | D8: P0 | E8: Fail (no Retry / false insufficient credits) | F8: Retry UI; new idempotency only after terminal fail | G8: Yes | H8: Blocked | I8: BLK-EDGE / BLK-PY | J8: Not Run | N8: Retry must not claim insufficient credits if balance remains.
A9: TC-GOV-012 | B9: Government Exams | C9: Anushka | D9: P0 | E9: Not proven live | F9: AI fill Realistic/Custom only; Official fail-closed | G9: Yes | H9: Blocked | I9: BLK-PY / BLK-CFG (AI-down scenario needs QA-lead flag) | J9: Not Run | N9: Official must never be AI-labeled.
A10: TC-GOV-015 | B10: Government Exams | C10: Anushka | D10: P0 | E10: Blocked (no live paper) | F10: Server started_at / expires_at via start-exam | G10: Yes | H10: Blocked | I10: BLK-EDGE (start-exam 404 until deploy) | J10: Not Run | N10: Client must not forever-extend the clock.
A11: TC-GOV-016 | B11: Government Exams | C11: Anushka | D11: P0 | E11: Blocked | F11: Palette states restored from test_responses | G11: Yes | H11: Blocked | I11: BLK-EDGE / BLK-PY | J11: Not Run | N11: Unanswered / answered / marked / answered+marked.
A12: TC-GOV-017 | B12: Government Exams | C12: Anushka | D12: P0 | E12: Blocked | F12: Versioned autosave; stale skip; ATTEMPT_EXPIRED | G12: Yes | H12: Blocked | I12: BLK-EDGE (save-test-answer) | J12: Not Run | N12: Navigate + refresh must restore or warn honestly.
A13: TC-GOV-018 | B13: Government Exams | C13: Anushka | D13: P0 | E13: Blocked | F13: submit-test duplicate replay; no silent rescore | G13: Yes | H13: Blocked | I13: BLK-EDGE / BLK-PY | J13: Not Run | N13: Partial submit warning + stable result.
A14: TC-GOV-019 | B14: Government Exams | C14: Anushka | D14: P0 | E14: Blocked | F14: Results persist on mock_tests + history routes | G14: Yes | H14: Blocked | I14: BLK-EDGE / BLK-PY | J14: Not Run | N14: Logout/login must still show owner result.
A15: TC-GOV-020 | B15: Government Exams | C15: Anushka | D15: P0 | E15: Fail (charge before paper) | F15: reserve → finalize on completed; release on fail/cancel | G15: Yes | H15: Blocked | I15: BLK-MIG / BLK-EDGE | J15: Not Run | N15: Failed generate must not keep reserved credits.
A16: TC-GOV-024 | B16: Government Exams | C16: Anushka | D16: P1 | E16: Fail (duplicate Generate) | F16: Idempotency key; 409 replay no second reservation | G16: Yes | H16: Blocked | I16: BLK-EDGE / BLK-MIG | J16: Not Run | N16: Double-click Generate = one job.
... A18: TC-API-005 | B18: API / Network Observation | C18: Anushka | D18: P0 | E18: Fail (429 drops in-flight job) | F18: 429/5xx stay in-flight; 8 transient retries | G18: Yes | H18: Blocked | I18: BLK-EDGE | J18: Not Run | N18: Do not Fail a 429 that recovers.
A19: DEF-013 / TC-GOV-010 | B19: Government Exams | C19: Anushka | D19: P0 | E19: Fail (bootstrap trap / infinite Searching…) | F19: Gov browse during onboarding recovery; search abort/latest-wins | G19: Partial — hub is user-visible today | H19: Yes | J19: Not Run | N19: DEF-001 related. Hub must not infinite spinner.
A20: TC-ADM-022 | B20: Admin Portal | C20: Anushka | D20: P1 | E20: Fail (topic Apply-only + dual empty) | F20: Live debounce + one empty card | G20: No (admin UI) | H20: Yes | J20: Not Run | N20: Question review: one empty state, Apply live.
A21: TC-MOD-SMOKE-GOV | B21: Module Smoke | C21: Anushka | D21: P0 | E21: Fail — infinite search spinner on /app/mock-test | F21: Search debounce/abort; profile recovery browse | G21: No | H21: Yes | J21: Not Run | N21: Re-run module smoke on Gov hub. Opening hub ≠ Pass.
A22: TC-PREP-COACH-CREDITS | B22: Practice Coach | C22: Anushka | D22: P1 | E22: prep-tool 401/unknown looked like no credits | F22: JWT via fetchEdge; credit-first; raw_prompt alias | G22: No | H22: Yes | I22: BLK-EDGE if prep-tool 404 | J22: Not Run | N22: Coach/docs surface must not say insufficient credits on 401.
A23: TC-SES-002 | B23: Sessions | C23: Sultana | D23: P0 | E23: Fail (session detail 500) | F23: get_owned_session_detail owner RPC; Not scored empty | G23: Yes if migration unapplied | H23: Yes | I23: BLK-MIG if 500 persists | J23: Not Run | N23: Must show transcript/score OR honest empty — never 500.
A24: TC-CR-003 | B24: Credits | C24: Sultana | D24: P0 | E24: Fail (zero-credit 400 unknown tool) | F24: 402 before tool_id; raw_prompt alias | G24: No | H24: Yes | J24: Not Run | N24: ZERO_CREDIT_01. Block must be credits, not unknown tool.
A25: TC-CR-004 | B25: Credits | C25: Sultana | D25: P1 | E25: Fail (past-due reused as low-credit) | F25: Separate qa.lowcredit@ fixture | G25: No | H25: Yes | I25: BLK-CRED if qa.lowcredit@ missing | J25: Not Run | N25: Use LOW_CREDIT_01 only — not past-due.
A26: TC-CR-005 | B26: Credits | C26: Sultana | D26: P1 | E26: Fail (wrong fixture) | F26: qa.exactcredit@ exact-boundary | G26: No | H26: Yes | I26: BLK-CRED if qa.exactcredit@ missing | J26: Not Run | N26: Use EXACT_CREDIT_01.
A27: TC-BILL-007 | B27: Billing | C27: Sultana | D27: P1 | E27: N/A / not run | F27: BillingHistory refund filter from ledger | G27: No | H27: Yes | I27: BLK-CFG if no refund rows in sandbox | J27: Not Run | N27: Honest empty refund list is Pass if product has no refunds.
A28: TC-PREP-003 | B28: Prep Lab | C28: Sultana | D28: P1 | E28: Fail (prep-tool 401/unknown) | F28: JWT fetchEdge; credit-first | G28: No | H28: Yes | I28: BLK-EDGE if function 404 | J28: Not Run | N28: Unknown/401 must not look like no credits.
A29: DOCX-30-001/002 | B29: Credits | C29: Sultana | D29: P2 | E29: Fail (Help catalog drift) | F29: Help fallback from creditEconomics | G29: No | H29: Yes | J29: Not Run | N29: Help copy for free plan / extra credits matches product.
A30: TC-AUTH-008 | B30: Authentication | C30: Venkat | D30: P0 | E30: Fail (raw email_not_confirmed) | F30: formatSupabaseAuthError on login + OAuth | G30: No | H30: Yes | J30: Not Run | N30: Human-readable verify-email copy, not raw error code.
A31: TC-AUTH-014 | B31: Authentication | C31: Venkat | D31: P0 | E31: Fail (broken Google CTA) | F31: Hide CTA when isOAuthProviderEnabled is false | G31: No | H31: Yes | I31: BLK-CFG if Google enabled but 400 | J31: Not Run | N31: Visible dead Google button = Fail. Hidden = Pass.
A32: TC-AUTH-015 | B32: Authentication | C32: Venkat | D32: P1 | E32: Fail (MFA paused) | F32: MFA_ENFORCEMENT_PAUSED = false | G32: No | H32: Yes | J32: Not Run | N32: Security/MFA controls visible and consistent.
A33: TC-ONB-002 | B33: Onboarding | C33: Venkat | D33: P0 | E33: Fail (no fixture) | F33: Seed qa.onboarding@ | G33: No | H33: Yes | I33: BLK-CRED if NEW_USER_01 missing | J33: Not Run | N33: Use NEW_USER_01 / qa.onboarding@.
A34: TC-ONB-004 | B34: Onboarding | C34: Venkat | D34: P0 | E34: Fail (popstate / step lost) | F34: Persist onboarding_step on Next/Back | G34: No | H34: Yes | J34: Not Run | N34: Browser Back must restore step.
A35: TC-ONB-005 | B35: Onboarding | C35: Venkat | D35: P1 | E35: Fail | F35: onboarding_step persist | G35: No | H35: Yes | J35: Not Run | N35: Refresh mid-wizard restores step.
A36: TC-ONB-006 | B36: Onboarding | C36: Venkat | D36: P1 | E36: Fail | F36: onboarding_step persist | G36: No | H36: Yes | J36: Not Run | N36: Next/Back do not skip required fields.
A37: TC-ONB-007 | B37: Onboarding | C37: Venkat | D37: P1 | E37: Fail | F37: onboarding_step persist | G37: No | H37: Yes | J37: Not Run | N37: Complete onboarding lands in app.
A38: TC-AUTH-010 / D-012 | B38: Authentication | C38: Venkat | D38: P1 | E38: Fail (reset width + inbox copy) | F38: AuthShell max-w-md; spam/wait copy | G38: No | H38: Yes | J38: Not Run | N38: Reset form readable; copy mentions spam/wait.
A39: TC-SET-015 | B39: Settings | C39: Venkat | D39: P0 | E39: Fail (delete 429 on retry) | F39: Skip rate limit when existingOp exists | G39: No | H39: Yes | J39: Not Run | N39: DISPOSABLE_01 only. Re-seed after.
A40: TC-SCH-002 | B40: Interview Scheduler | C40: Venkat | D40: P1 | E40: Fail (local Date parse) | F40: IANA zonedWallTimeToUtc + Zod schema | G40: No | H40: Yes | J40: Not Run | N40: Edit/reschedule keeps intended IST wall time.
A41: TC-SCH-003 | B41: Interview Scheduler | C41: Venkat | D41: P1 | E41: Fail (timezone) | F41: IANA timezone validation | G41: No | H41: Yes | J41: Not Run | N41: Invalid date/timezone blocked with validation.
A42: TC-SCH-004 | B42: Interview Scheduler | C42: Venkat | D42: P1 | E42: Fail (Calendar Connect 501) | F42: Disabled Not configured when probe 501 | G42: No | H42: Yes | I42: BLK-CFG if Calendar later enabled | J42: Not Run | N42: Visible dead Connect = Fail. Not configured = Pass.
...

Sheet 00d Live Gov Exam Proof
A1: 00d Live Gov Exam Proof
A2: PRE-FILLED for you. ONLY update peach columns: Actual Result | Pass/Fail | Defect ID | Execution Date | Notes. Tester is pre-assigned (Anushka / Sultana / Venkat). Complete assigned work within 2 days. Mark section ALL FILLED on '00b Section Completion Gate' ONLY when every case has Pass/Fail ≠ Not Run AND Actual Result filled. Black-box only — no source/DB/server access. Opening a page is NOT Pass.
A4: Test Case ID | B4: Module | C4: Sub-Module | D4: Feature | E4: Workflow | F4: Priority | G4: Severity | H4: Test Type | I4: User Type | J4: Role | K4: Account ID | L4: Preconditions | M4: Test Environment | N4: Test Data | O4: Exact Steps | P4: Expected Result (per step) | Q4: Final Expected Result | R4: Validation Points | S4: Screenshot / Evidence Requirement | T4: Actual Result | U4: Pass / Fail | V4: Defect ID | W4: Tester | X4: Execution Date | Y4: Notes
A5: TC-GOV-LIVE-01 | B5: Government Exams | C5: Live proof | D5: Hub loads, no infinite Searching… | E5: Hub loads, no infinite Searching… | F5: P0 | G5: Critical | H5: Positive | I5: Authenticated | J5: user | K5: PRO_USER_01 | L5: Logged in. App URL available. Browser DevTools permitted. | M5: Closed Beta / QA Target | N5: Use approved test credentials from Test Accounts sheet. | O5: 1. Login PRO_USER_01. 2. Open https://clarify.ai.sltfinanceindia.com/app/mock-test. 3. Wait ≤15s. 4. Type a letter in search; confirm spinner ends. | P5: 1. Auth ok. 2. Hub renders. 3. No infinite spinner/blank. 4. Search idle or results — not stuck Searching… | Q5: Gov hub is usable without infinite search. | R5: Observable UI state matches expected results; no unexplained spinner; no silent failure; persistence verified via refresh where applicable. | S5: Screenshot of final state. On fail: URL, visible error, Network status if DevTools allowed. | U5: Not Run | W5: Anushka | Y5: Runnable now. DEF-001 retest.
A6: TC-GOV-LIVE-02 | B6: Government Exams | C6: Live proof | D6: Search valid exam (SSC/IBPS/UPSC alias) | E6: Search valid exam (SSC/IBPS/UPSC alias) | F6: P0 | G6: Critical | H6: Positive | I6: Authenticated | J6: user | K6: PRO_USER_01 | L6: Logged in. App URL available. Browser DevTools permitted. | M6: Closed Beta / QA Target | N6: Use approved test credentials from Test Accounts sheet. | O6: 1. Search a known exam/alias (SSC, IBPS, UPSC if listed). 2. Select a result. 3. Open exam detail. | P6: 1. Suggestions appear (latest-wins; no stale overwrite). 2. Selection sticks. 3. Detail loads. | Q6: Valid exam search returns a selectable exam. | R6: Observable UI state matches expected results; no unexplained spinner; no silent failure; persistence verified via refresh where applicable. | S6: Screenshot of final state. On fail: URL, visible error, Network status if DevTools allowed. | U6: Not Run | W6: Anushka
A7: TC-GOV-LIVE-04 | B7: Government Exams | C7: Live proof | D7: Detail + pattern + syllabus | E7: Detail + pattern + syllabus | F7: P0 | G7: Critical | H7: Positive | I7: Authenticated | J7: user | K7: PRO_USER_01 | L7: Logged in. App URL available. Browser DevTools permitted. | M7: Closed Beta / QA Target | N7: Use approved test credentials from Test Accounts sheet. | O7: 1. Open exam detail. 2. Confirm pattern (sections/marks) visible. 3. Confirm syllabus OR honest SYLLABUS_NOT_AVAILABLE (no charge). | P7: 1. Detail loads. 2. Pattern shown. 3. Syllabus present or honest unavailable — not a silent charge. | Q7: Pattern/syllabus are honest. | R7: Observable UI state matches expected results; no unexplained spinner; no silent failure; persistence verified via refresh where applicable. | S7: Screenshot of final state. On fail: URL, visible error, Network status if DevTools allowed. | U7: Not Run | W7: Anushka
A8: TC-GOV-LIVE-05 | B8: Government Exams | C8: Live proof | D8: Review availability == Generate availability | E8: Review availability == Generate availability | F8: P0 | G8: Critical | H8: Positive | I8: Authenticated | J8: user | K8: PRO_USER_01 | L8: Logged in. App URL available. Browser DevTools permitted. | M8: Closed Beta / QA Target | N8: Use approved test credentials from Test Accounts sheet. | O8: 1. Record available count on Review. 2. Open Generate for same config. 3. Compare numbers. | P8: 1. Review number recorded. 2. Generate loads. 3. Same available count. Disagree = Fail. | Q8: Review and Generate share one availability snapshot. | R8: Observable UI state matches expected results; no unexplained spinner; no silent failure; persistence verified via refresh where applicable. | S8: Screenshot of final state. On fail: URL, visible error, Network status if DevTools allowed. | U8: Not Run | W8: Anushka | Y8: If Edge 404 / Python worker down / migrations missing: Pass/Fail = Blocked with BLK-EDGE, BLK-PY, or BLK-MIG. Do not Fail undeployed stack.
A9: TC-GOV-LIVE-06 | B9: Government Exams | C9: Live proof | D9: Custom Practice generate → completed paper | E9: Custom Practice generate → completed paper | F9: P0 | G9: Critical | H9: Positive | I9: Authenticated | J9: user | K9: SUFFICIENT_CREDIT_01 | L9: Logged in. App URL available. Browser DevTools permitted. | M9: Closed Beta / QA Target | N9: Use approved test credentials from Test Accounts sheet. | O9: 1. Note credits. 2. Custom Practice within min/max. 3. Generate once. 4. Wait until completed with mock_test_id. 5. Start Exam. | P9: 1. Balance recorded. 2. Config accepted. 3. Progress shown. 4. Terminal completed (not infinite Generating). 5. Runner opens. | Q9: P0 release gate: a real Custom Practice paper exists on the live URL. | R9: Observable UI state matches expected results; no unexplained spinner; no silent failure; persistence verified via refresh where applicable. | S9: Screenshot of final state. On fail: URL, visible error, Network status if DevTools allowed. | U9: Not Run | W9: Anushka | Y9: GO requires this Pass (or Full Mock equivalent). If Edge 404 / Python worker down / migrations missing: Pass/Fail = Blocked with BLK-EDGE, BLK-PY, or BLK-MIG. Do not Fail undeployed stack.
A10: TC-GOV-LIVE-07 | B10: Government Exams | C10: Live proof | D10: Full Mock startable or honest CONTENT_INSUFFICIENT | E10: Full Mock startable or honest CONTENT_INSUFFICIENT | F10: P0 | G10: Critical | H10: Positive | I10: Authenticated | J10: user | K10: SUFFICIENT_CREDIT_01 | L10: Logged in. App URL available. Browser DevTools permitted. | M10: Closed Beta / QA Target | N10: Use approved test credentials from Test Accounts sheet. | O10: 1. Choose Full Mock. 2. Generate. 3. If bank short, confirm fail-closed message. 4. If completed, Start Exam works even if count is short of pattern (toast OK). | P10: 1. Mode selected. 2. Job runs. 3. Honest CONTENT_INSUFFICIENT is Pass. 4. Infinite Generating is Fail. Completed+short still startable. | Q10: Full Mock does not trap the user. | R10: Observable UI state matches expected results; no unexplained spinner; no silent failure; persistence verified via refresh where applicable. | S10: Screenshot of final state. On fail: URL, visible error, Network status if DevTools allowed. | U10: Not Run | W10: Anushka | Y10: If Edge 404 / Python worker down / migrations missing: Pass/Fail = Blocked with BLK-EDGE, BLK-PY, or BLK-MIG. Do not Fail undeployed stack.
A11: TC-GOV-LIVE-08 | B11: Government Exams | C11: Live proof | D11: Official/PYQ fail-closed, never AI-labeled Official | E11: Official/PYQ fail-closed, never AI-labeled Official | F11: P0 | G11: Critical | H11: Negative | I11: Authenticated | J11: user | K11: SUFFICIENT_CREDIT_01 | L11: Logged in. App URL available. Browser DevTools permitted. | M11: Closed Beta / QA Target | N11: Use approved test credentials from Test Accounts sheet. | O11: 1. Choose Official / Previous Year if offered. 2. Generate or observe empty. 3. Confirm questions are not AI-written labeled Official. | P11: 1. Mode visible or hidden honestly. 2. Empty/fail-closed OR licensed PYQ. 3. AI fill labeled Official = Fail. | Q11: Official stays fail-closed. | R11: Observable UI state matches expected results; no unexplained spinner; no silent failure; persistence verified via refresh where applicable. | S11: Screenshot of final state. On fail: URL, visible error, Network status if DevTools allowed. | U11: Not Run | W11: Anushka | Y11: BLK-BANK accepted only AFTER LIVE-06 Pass.
A12: TC-GOV-LIVE-09 | B12: Government Exams | C12: Live proof | D12: Duplicate Generate = one job, no double charge | E12: Duplicate Generate = one job, no double charge | F12: P0 | G12: Critical | H12: Negative | I12: Authenticated | J12: user | K12: SUFFICIENT_CREDIT_01 | L12: Logged in. App URL available. Browser DevTools permitted. | M12: Closed Beta / QA Target | N12: Use approved test credentials from Test Accounts sheet. | O12: 1. Note credits. 2. Click Generate. 3. Immediately click Generate again. 4. Observe jobs and credits. | P12: 1. Baseline. 2. First job starts. 3. Second click does not create a second reservation. 4. One in-flight paper or 409 replay. | Q12: Duplicate Generate is safe. | R12: Observable UI state matches expected results; no unexplained spinner; no silent failure; persistence verified via refresh where applicable. | S12: Screenshot of final state. On fail: URL, visible error, Network status if DevTools allowed. | U12: Not Run | W12: Anushka | Y12: If Edge 404 / Python worker down / migrations missing: Pass/Fail = Blocked with BLK-EDGE, BLK-PY, or BLK-MIG. Do not Fail undeployed stack.
A13: TC-GOV-LIVE-10 | B13: Government Exams | C13: Live proof | D13: Refresh during Generating = restore, not trap | E13: Refresh during Generating = restore, not trap | F13: P0 | G13: Critical | H13: Negative | I13: Authenticated | J13: user | K13: SUFFICIENT_CREDIT_01 | L13: Logged in. App URL available. Browser DevTools permitted. | M13: Closed Beta / QA Target | N13: Use approved test credentials from Test Accounts sheet. | O13: 1. Start Generate. 2. Refresh while Generating. 3. Confirm restore or truthful fail/retry — not infinite Generating. | P13: 1. In-flight. 2. Refresh. 3. Recoverable truthful status. | Q13: Refresh does not trap generation. | R13: Observable UI state matches expected results; no unexplained spinner; no silent failure; persistence verified via refresh where applicable. | S13: Screenshot of final state. On fail: URL, visible error, Network status if DevTools allowed. | U13: Not Run | W13: Anushka | Y13: If Edge 404 / Python worker down / migrations missing: Pass/Fail = Blocked with BLK-EDGE, BLK-PY, or BLK-MIG. Do not Fail undeployed stack.
A14: TC-GOV-LIVE-11 | B14: Government Exams | C14: Live proof | D14: Retry after fail; no false insufficient-credits | E14: Retry after fail; no false insufficient-credits | F14: P0 | G14: Critical | H14: Negative | I14: Authenticated | J14: user | K14: SUFFICIENT_CREDIT_01 | L14: Logged in. App URL available. Browser DevTools permitted. | M14: Closed Beta / QA Target | N14: Use approved test credentials from Test Accounts sheet. | O14: 1. If job fails (or after cancel), read error. 2. Click Retry. 3. Confirm credit message matches real balance. | P14: 1. Clear failure. 2. Retry re-attempts. 3. No false insufficient credits. | Q14: Failures are retryable and truthful. | R14: Observable UI state matches expected results; no unexplained spinner; no silent failure; persistence verified via refresh where applicable. | S14: Screenshot of final state. On fail: URL, visible error, Network status if DevTools allowed. | U14: Not Run | W14: Anushka | Y14: If Edge 404 / Python worker down / migrations missing: Pass/Fail = Blocked with BLK-EDGE, BLK-PY, or BLK-MIG. Do not Fail undeployed stack.
A15: TC-GOV-LIVE-12 | B15: Government Exams | C15: Live proof | D15: Failed/cancelled generate refunds reserved credits | E15: Failed/cancelled generate refunds reserved credits | F15: P0 | G15: Critical | H15: Positive | I15: Authenticated | J15: user | K15: SUFFICIENT_CREDIT_01 | L15: Logged in. App URL available. Browser DevTools permitted. | M15: Closed Beta / QA Target | N15: Use approved test credentials from Test Accounts sheet. | O15: 1. Note balance. 2. Start generate then Cancel, or wait for fail. 3. Refresh balance. | P15: 1. Baseline. 2. Cancel/fail terminal. 3. Reserved credits released — balance restored. | Q15: Fail/cancel releases reservation. | R15: Observable UI state matches expected results; no unexplained spinner; no silent failure; persistence verified via refresh where applicable. | S15: Screenshot of final state. On fail: URL, visible error, Network status if DevTools allowed. | U15: Not Run | W15: Anushka | Y15: If Edge 404 / Python worker down / migrations missing: Pass/Fail = Blocked with BLK-EDGE, BLK-PY, or BLK-MIG. Do not Fail undeployed stack.
A16: TC-GOV-LIVE-13 | B16: Government Exams | C16: Live proof | D16: Successful generate finalizes credits only when paper exists | E16: Successful generate finalizes credits only when paper exists | F16: P0 | G16: Critical | H16: Positive | I16: Authenticated | J16: user | K16: SUFFICIENT_CREDIT_01 | L16: Logged in. App URL available. Browser DevTools permitted. | M16: Closed Beta / QA Target | N16: Use approved test credentials from Test Accounts sheet. | O16: 1. Note balance. 2. Complete a paper (LIVE-06). 3. Confirm deduction happens after completed+mock_test_id, not at click. | P16: 1. Baseline. 2. Paper exists. 3. Charge matches UI only on success path. | Q16: Credits finalize only on completed paper. | R16: Observable UI state matches expected results; no unexplained spinner; no silent failure; persistence verified via refresh where applicable. | S16: Screenshot of final state. On fail: URL, visible error, Network status if DevTools allowed. | U16: Not Run | W16: Anushka | Y16: If Edge 404 / Python worker down / migrations missing: Pass/Fail = Blocked with BLK-EDGE, BLK-PY, or BLK-MIG. Do not Fail undeployed stack.
A17: TC-GOV-LIVE-14 | B17: Government Exams | C17: Live proof | D17: Start Exam uses server timer | E17: Start Exam uses server timer | F17: P0 | G17: Critical | H17: Positive | I17: Authenticated | J17: user | K17: SUFFICIENT_CREDIT_01 | L17: Logged in. App URL available. Browser DevTools permitted. | M17: Closed Beta / QA Target | N17: Use approved test credentials from Test Accounts sheet. | O17: 1. Start Exam on a completed paper. 2. Note timer. 3. Refresh. 4. Confirm time did not reset/extend. | P17: 1. Runner starts. 2. Countdown visible. 3. Refresh. 4. Server started_at/expires_at honored. | Q17: Client cannot forever-extend the exam clock. | R17: Observable UI state matches expected results; no unexplained spinner; no silent failure; persistence verified via refresh where applicable. | S17: Screenshot of final state. On fail: URL, visible error, Network status if DevTools allowed. | U17: Not Run | W17: Anushka | Y17: start-exam 404 = BLK-EDGE.
A18: TC-GOV-LIVE-15 | B18: Government Exams | C18: Live proof | D18: Palette states | E18: Palette states | F18: P0 | G18: Critical | H18: Positive | I18: Authenticated | J18: user | K18: SUFFICIENT_CREDIT_01 | L18: Logged in. App URL available. Browser DevTools permitted. | M18: Closed Beta / QA Target | N18: Use approved test credentials from Test Accounts sheet. | O18: 1. Leave one unanswered. 2. Answer one. 3. Mark one unanswered. 4. Answer+mark one. 5. Observe current highlight. | P18: 1–5. Palette shows unanswered / answered / marked / answered+marked / current. | Q18: Palette states are complete and visible. | R18: Observable UI state matches expected results; no unexplained spinner; no silent failure; persistence verified via refresh where applicable. | S18: Screenshot of final state. On fail: URL, visible error, Network status if DevTools allowed. | U18: Not Run | W18: Anushka
A19: TC-GOV-LIVE-16 | B19: Government Exams | C19: Live proof | D19: Autosave + mark-for-review persist | E19: Autosave + mark-for-review persist | F19: P0 | G19: Critical | H19: Persistence | I19: Authenticated | J19: user | K19: SUFFICIENT_CREDIT_01 | L19: Logged in. App URL available. Browser DevTools permitted. | M19: Closed Beta / QA Target | N19: Use approved test credentials from Test Accounts sheet. | O19: 1. Answer Q1 and mark for review. 2. Jump to Q2 and back. 3. Refresh. 4. Confirm answer + marked restored. | P19: 1. Saved. 2. Retained on navigate. 3. Refresh. 4. Both answer and mark persist (or honest warning). | Q19: Autosave and mark-for-review survive navigate and refresh. | R19: Observable UI state matches expected results; no unexplained spinner; no silent failure; persistence verified via refresh where applicable. | S19: Screenshot of final state. On fail: URL, visible error, Network status if DevTools allowed. | U19: Not Run | W19: Anushka | Y19: BLK-EDGE if save-test-answer missing.
A20: TC-GOV-LIVE-17 | B20: Government Exams | C20: Live proof | D20: Submit + expiry + no corrupt double-submit | E20: Submit + expiry + no corrupt double-submit | F20: P0 | G20: Critical | H20: Positive | I20: Authenticated | J20: user | K20: SUFFICIENT_CREDIT_01 | L20: Logged in. App URL available. Browser DevTools permitted. | M20: Closed Beta / QA Target | N20: Use approved test credentials from Test Accounts sheet. | O20: 1. Leave some unanswered. 2. Submit (warning OK). 3. Try submit again. 4. On a second attempt, let timer expire if a short paper exists. | P20: 1. Partial paper. 2. Submitted; score shown. 3. Second submit does not change score. 4. Expiry auto-submits or locks. | Q20: Submit is stable; expiry is enforced. | R20: Observable UI state matches expected results; no unexplained spinner; no silent failure; persistence verified via refresh where applicable. | S20: Screenshot of final state. On fail: URL, visible error, Network status if DevTools allowed. | U20: Not Run | W20: Anushka
A21: TC-GOV-LIVE-18 | B21: Government Exams | C21: Live proof | D21: Result in history after logout/login | E21: Result in history after logout/login | F21: P0 | G21: Critical | H21: Persistence | I21: Authenticated | J21: user | K21: SUFFICIENT_CREDIT_01 | L21: Logged in. App URL available. Browser DevTools permitted. | M21: Closed Beta / QA Target | N21: Use approved test credentials from Test Accounts sheet. | O21: 1. After submit, open results. 2. Logout. 3. Login same user. 4. Open history/results. | P21: 1. Score visible. 2. Logged out. 3. Re-auth. 4. Same result still available to owner. | Q21: Results persist across sessions. | R21: Observable UI state matches expected results; no unexplained spinner; no silent failure; persistence verified via refresh where applicable. | S21: Screenshot of final state. On fail: URL, visible error, Network status if DevTools allowed. | U21: Not Run | W21: Anushka
A22: TC-GOV-LIVE-19 | B22: Government Exams | C22: Live proof | D22: USER_B cannot open USER_A paper/result URL | E22: USER_B cannot open USER_A paper/result URL | F22: P0 | G22: Critical | H22: Security | I22: Authenticated | J22: user | K22: USER_A_01 | L22: Logged in. App URL available. Browser DevTools permitted. | M22: Closed Beta / QA Target | N22: Use approved test credentials from Test Accounts sheet. | O22: 1. As USER_A copy results or session URL. 2. Login USER_B. 3. Paste URL. | P22: 1. A has URL. 2. B session. 3. Denied/not found — no A questions or scores. | Q22: Gov papers/results are owner-isolated. | R22: Observable UI state matches expected results; no unexplained spinner; no silent failure; persistence verified via refresh where applicable. | S22: Screenshot of final state. On fail: URL, visible error, Network status if DevTools allowed. | U22: Not Run | W22: Anushka
A23: TC-GOV-LIVE-20 | B23: Government Exams | C23: Live proof | D23: Free user plan gate | E23: Free user plan gate | F23: P0 | G23: Critical | H23: Security | I23: Authenticated | J23: user | K23: FREE_USER_01 | L23: Logged in. App URL available. Browser DevTools permitted. | M23: Closed Beta / QA Target | N23: Use approved test credentials from Test Accounts sheet. | O23: 1. As FREE_USER_01 open generate for a gated action. 2. Observe upgrade/gate. | P23: 1. Attempt. 2. Clear gate — no unauthorized full generate. | Q23: Free users cannot bypass paid gov-exam generate. | R23: Observable UI state matches expected results; no unexplained spinner; no silent failure; persistence verified via refresh where applicable. | S23: Screenshot of final state. On fail: URL, visible error, Network status if DevTools allowed. | U23: Not Run | W23: Anushka
A24: TC-GOV-LIVE-21 | B24: Government Exams | C24: Live proof | D24: Zero-credit / low-credit truthful | E24: Zero-credit / low-credit truthful | F24: P0 | G24: Critical | H24: Negative | I24: Authenticated | J24: user | K24: ZERO_CREDIT_01 | L24: Logged in. App URL available. Browser DevTools permitted. | M24: Closed Beta / QA Target | N24: Use approved test credentials from Test Accounts sheet. | O24: 1. As ZERO_CREDIT_01 attempt generate. 2. As LOW_CREDIT_01 (qa.lowcredit@) observe warning. 3. Confirm neither is the past-due account. | P24: 1. Zero blocked with buy/upgrade — not unknown tool. 2. Low-credit warning if product has threshold. 3. Fixtures are qa.zero@ / qa.lowcredit@ / qa.exactcredit@. | Q24: Credit fixtures are truthful and distinct from past-due. | R24: Observable UI state matches expected results; no unexplained spinner; no silent failure; persistence verified via refresh where applicable. | S24: Screenshot of final state. On fail: URL, visible error, Network status if DevTools allowed. | U24: Not Run | W24: Anushka | Y24: BLK-CRED if fixtures missing.
A25: TC-GOV-LIVE-23 | B25: Government Exams | C25: Live proof | D25: 429/409 during poll stays in-flight | E25: 429/409 during poll stays in-flight | F25: P0 | G25: Critical | H25: API Observation | I25: Authenticated | J25: user | K25: SUFFICIENT_CREDIT_01 | L25: Logged in. App URL available. Browser DevTools permitted. | M25: Closed Beta / QA Target | N25: Use approved test credentials from Test Accounts sheet. | O25: 1. Start Generate. 2. Watch Network for poll 429/409/5xx. 3. Confirm UI stays Generating (backoff) and is not SESSION_ACTION 20/min trapped. | P25: 1. Job in-flight. 2. Transient errors observed or documented as not seen. 3. Job recovers or fails honestly — not a 20/min session trap. | Q25: Poll uses JOB_POLL backoff; transient errors stay in-flight. | R25: Observable UI state matches expected results; no unexplained spinner; no silent failure; persistence verified via refresh where applicable. | S25: Screenshot of final state. On fail: URL, visible error, Network status if DevTools allowed. | U25: Not Run | W25: Anushka | Y25: If Edge 404 / Python worker down / migrations missing: Pass/Fail = Blocked with BLK-EDGE, BLK-PY, or BLK-MIG. Do not Fail undeployed stack.
A26: TC-GOV-LIVE-03 | B26: Government Exams | C26: Live proof | D26: Nonsense search empty, no crash | E26: Nonsense search empty, no crash | F26: P1 | G26: Major | H26: Negative | I26: Authenticated | J26: user | K26: PRO_USER_01 | L26: Logged in. App URL available. Browser DevTools permitted. | M26: Closed Beta / QA Target | N26: Use approved test credentials from Test Accounts sheet. | O26: 1. Search 'zzzz-not-an-exam-qqq'. 2. Observe empty state. | P26: 1. Query entered. 2. Empty/no-result; no crash; no random exam auto-selected. | Q26: Nonsense search is safe. | R26: Observable UI state matches expected results; no unexplained spinner; no silent failure; persistence verified via refresh where applicable. | S26: Screenshot of final state. On fail: URL, visible error, Network status if DevTools allowed. | U26: Not Run | W26: Anushka
A27: TC-GOV-LIVE-22 | B27: Government Exams | C27: Live proof | D27: AI-down fallback; Official stays fail-closed | E27: AI-down fallback; Official stays fail-closed | F27: P1 | G27: Major | H27: Negative | I27: Authenticated | J27: user | K27: SUFFICIENT_CREDIT_01 | L27: Logged in. App URL available. Browser DevTools permitted. | M27: Closed Beta / QA Target | N27: Use approved test credentials from Test Accounts sheet. | O27: 1. If QA lead marks AI-impaired, generate Realistic/Custom. 2. Observe fallback paper OR honest fail. 3. Official must still fail-closed. | P27: 1. Scenario started. 2. Not infinite Generating; no false credit error. 3. Official never AI-filled. | Q27: AI-down is honest; Official never uses AI. | R27: Observable UI state matches expected results; no unexplained spinner; no silent failure; persistence verified via refresh where applicable. | S27: Screenshot of final state. On fail: URL, visible error, Network status if DevTools allowed. | U27: Not Run | W27: Anushka | Y27: Coordinate AI-down with QA lead. If Edge 404 / Python worker down / migrations missing: Pass/Fail = Blocked with BLK-EDGE, BLK-PY, or BLK-MIG. Do not Fail undeployed stack.
A28: TC-GOV-LIVE-24 | B28: Government Exams | C28: Live proof | D28: Admin ingest never auto-publishes | E28: Admin ingest never auto-publishes | F28: P1 | G28: Major | H28: Positive | I28: Authenticated | J28: admin | K28: ADMIN_USER_01 | L28: Logged in. App URL available. Browser DevTools permitted. | M28: Closed Beta / QA Target | N28: Use approved test credentials from Test Accounts sheet. | O28: 1. Login ADMIN_USER_01. 2. Open https://clarify.ai.sltfinanceindia.com/app/admin/gov/ingest. 3. Upload a small PDF if allowed. 4. Confirm queued/needs_review — questions not live on hub. 5. On question-review, APPROVE/REJECT required before publish. | P28: 1. Admin auth. 2. Ingest UI loads. 3. 202 queued or honest size limit. 4. OCR/unpublished. 5. No auto-publish. | Q28: Ingest stays unpublished until review. | R28: Observable UI state matches expected results; no unexplained spinner; no silent failure; persistence verified via refresh where applicable. | S28: Screenshot of final state. On fail: URL, visible error, Network status if DevTools allowed. | U28: Not Run | W28: Anushka | Y28: Heavy PDF 502 with no refund is Fail if credits charged.

Sheet 01 Application Inventory
A1: 01 — Application Inventory (user-observable)
A2: Classify ONLY after manual execution. Opening a route ≠ Fully Working. All rows start as PENDING MANUAL CLASSIFICATION. Tester pre-assigned (Anushka / Sultana / Venkat).
A4: Area | B4: Feature / Surface | C4: Route / URL | D4: Observable Entry Point | E4: Primary Role | F4: Classification | G4: Evidence / Notes | H4: Tester | I4: Date | J4: Defect ID
A5: Public | B5: Landing page | C5: https://clarify.ai.sltfinanceindia.com/ | D5: Open site root | E5: Guest | F5: PENDING MANUAL CLASSIFICATION | G5: Marketing hero + CTAs | H5: Venkat
A6: Public | B6: Pricing | C6: https://clarify.ai.sltfinanceindia.com/pricing | D6: Nav → Pricing | E6: Guest | F6: PENDING MANUAL CLASSIFICATION | G6: Plans & CTAs | H6: Venkat
A7: Public | B7: Gov Exams marketing | C7: https://clarify.ai.sltfinanceindia.com/gov-exams | D7: Nav / CTA | E7: Guest | F7: PENDING MANUAL CLASSIFICATION | G7: Public marketing | H7: Venkat
A8: Public | B8: Help center | C8: https://clarify.ai.sltfinanceindia.com/help | D8: Footer / Help | E8: Guest | F8: PENDING MANUAL CLASSIFICATION | G8: Articles list | H8: Venkat
A9: Public | B9: Help article | C9: https://clarify.ai.sltfinanceindia.com/help/:slug | D9: Open article from Help | E9: Guest | F9: PENDING MANUAL CLASSIFICATION | G9: Article body | H9: Venkat
A10: Public | B10: Keyboard shortcuts | C10: https://clarify.ai.sltfinanceindia.com/shortcuts | D10: Footer / Help link | E10: Guest | F10: PENDING MANUAL CLASSIFICATION | G10: Shortcuts page | H10: Venkat
A11: Public | B11: Blog list | C11: https://clarify.ai.sltfinanceindia.com/blog | D11: Nav / footer | E11: Guest | F11: PENDING MANUAL CLASSIFICATION | G11: Posts list | H11: Venkat
A12: Public | B12: Blog post | C12: https://clarify.ai.sltfinanceindia.com/blog/:slug | D12: Open post | E12: Guest | F12: PENDING MANUAL CLASSIFICATION | G12: Post body | H12: Venkat
A13: Public | B13: Terms of Service | C13: https://clarify.ai.sltfinanceindia.com/terms | D13: Footer | E13: Guest | F13: PENDING MANUAL CLASSIFICATION | G13: Legal | H13: Venkat
A14: Public | B14: Privacy Policy | C14: https://clarify.ai.sltfinanceindia.com/privacy | D14: Footer | E14: Guest | F14: PENDING MANUAL CLASSIFICATION | G14: Legal | H14: Venkat
A15: Public | B15: Shared debrief | C15: https://clarify.ai.sltfinanceindia.com/share/:token | D15: Shared link | E15: Guest | F15: PENDING MANUAL CLASSIFICATION | G15: Token-gated share | H15: Venkat
A16: Public | B16: Certificate verification | C16: https://clarify.ai.sltfinanceindia.com/verify-certificate/:certificateId | D16: Public verify URL | E16: Guest | F16: PENDING MANUAL CLASSIFICATION | G16: Certificate check | H16: Venkat
... A130: Security | B130: Logged-out protected route | C130: https://clarify.ai.sltfinanceindia.com/app/dashboard | D130: Paste URL logged out | E130: Guest | F130: PENDING MANUAL CLASSIFICATION | G130: Must redirect login | H130: Venkat

Sheet 02 User Roles & Permissions
A1: 02 — User Roles & Permissions (black-box)
A2: Expected permissions as observed in the product UI/plan gates — not from source inspection.
A4: Role | B4: Description | C4: Can Access | D4: Cannot Access | E4: Primary Test Focus
A5: Guest | B5: Unauthenticated visitor | C5: Public pages, login/signup CTAs | D5: No app modules, no admin | E5: Public marketing & auth entry
A6: Unverified User | B6: Signed up, email not verified | C6: Verify-email screen | D6: Cannot enter /app until verified | E6: Email verification flow
A7: New / Onboarding User | B7: Verified, onboarding incomplete | C7: Onboarding wizard | D7: App shell blocked until complete | E7: Onboarding
A8: Free User | B8: plan free | C8: Core free features per plan gates | D8: Paid/pro-gated actions blocked or upgrade prompt | E8: Free plan QA
A9: Pro User | B9: plan pro | C9: Pro features + higher credits | D9: Enterprise-only if any | E9: Pro plan QA
A10: Max / Enterprise User | B10: plan enterprise / max | C10: Highest plan features & credits | D10: Admin still denied unless staff | E10: Max plan QA
A11: Zero Credit User | B11: Authenticated with 0 credits | C11: Browse UI; AI actions blocked gracefully | D11: Credit-consuming actions | E11: Credit exhaustion
A12: Low Credit User | B12: Credits near threshold | C12: Low-credit banners / warnings | D12: Actions that exceed balance | E12: Boundary credits
A13: Admin | B13: Staff role (admin) | C13: Full Admin portal + user app | D13: N/A | E13: Admin portal QA
A14: Moderator | B14: moderator role if assigned | C14: If UI exposes moderation tools | D14: Full admin may be denied | E14: Only if role is provisioned
A15: Banned / Suspended User | B15: Account banned | C15: Login rejected or safe ban message | D15: All app access | E15: Ban enforcement
A16: Expired Session User | B16: Valid account, stale session | C16: Re-auth / redirect to login | D16: Protected actions | E16: Session expiry

Sheet 03 Test Accounts
A1: 03 — Test Accounts (EMAIL + PASSWORD PRE-FILLED)
A2: Loaded from .env.qa.local for closed-beta QA. CONFIDENTIAL — QA team only. Use Account ID referenced in each test case.
A4: Test Account ID | B4: Role | C4: Plan | D4: Purpose | E4: Email / Username | F4: Password | G4: Credits (seed) | H4: Credential Location | I4: Environment | J4: Restrictions | K4: Expected Permissions | L4: Assigned Testers (shared)
A5: GUEST | B5: Guest | C5: none | D5: Public browsing — no login | E5: N/A — no login | F5: N/A | G5: — | H5: .env.qa.local (also copied here for closed-beta QA team only) | I5: Closed Beta / QA Target | J5: No credentials | K5: Public pages only | L5: Anushka, Sultana, Venkat
A6: FREE_USER_01 | B6: Free User | C6: free | D6: Free-plan feature testing | E6: qa.free@clarify.ai.test | F6: Qa!OWORccvwZOiv_jHC | G6: 50 | H6: .env.qa.local (also copied here for closed-beta QA team only) | I6: Closed Beta / QA Target | J6: Do not upgrade permanently | K6: Free entitlements | L6: Anushka, Sultana, Venkat
A7: FREE_USER_02 | B7: Free User (empty history) | C7: free | D7: Empty-state testing | E7: qa.free@clarify.ai.test | F7: Qa!OWORccvwZOiv_jHC | G7: 50 | H7: .env.qa.local (also copied here for closed-beta QA team only) | I7: Closed Beta / QA Target | J7: Prefer a clean/empty profile if available; else use FREE and skip history asserts | K7: Empty states | L7: Anushka, Sultana, Venkat
A8: PRO_USER_01 | B8: Pro User | C8: pro | D8: Pro features & credits | E8: qa.pro@clarify.ai.test | F8: Qa!AwHf4rrb5hLYudkp | G8: 1400 | H8: .env.qa.local (also copied here for closed-beta QA team only) | I8: Closed Beta / QA Target | J8: Primary product testing account | K8: Pro entitlements | L8: Anushka, Sultana, Venkat
A9: MAX_USER_01 | B9: Max/Enterprise User | C9: enterprise | D9: Max plan features | E9: qa.max@clarify.ai.test | F9: Qa!LkS_0RtB8I8uehUK | G9: 4000 | H9: .env.qa.local (also copied here for closed-beta QA team only) | I9: Closed Beta / QA Target | J9: Highest plan | K9: Max entitlements | L9: Anushka, Sultana, Venkat
A10: ADMIN_USER_01 | B10: Admin | C10: enterprise | D10: Admin portal testing | E10: qa.admin@clarify.ai.test | F10: Qa!TYw9VQk8y3KBZUnW | G10: 4000 | H10: .env.qa.local (also copied here for closed-beta QA team only) | I10: Closed Beta / QA Target | J10: Staff only — do not share outside QA team | K10: Admin + user app | L10: Anushka, Sultana, Venkat
A11: UNVERIFIED_01 | B11: Unverified | C11: free | D11: Email verification gate | E11: qa.unverified@clarify.ai.test | F11: Qa!3hXMIDuOJbS84CQx | G11: 50 | H11: .env.qa.local (also copied here for closed-beta QA team only) | I11: Closed Beta / QA Target | J11: Must remain unverified until AUTH-VERIFY cases done | K11: Verify-email only | L11: Anushka, Sultana, Venkat
A12: NEW_USER_01 | B12: Newly Registered / Onboarding | C12: free | D12: Signup + onboarding | E12: qa.onboarding@clarify.ai.test | F12: Qa!bYdJ5KfLTyQ68H79 | G12: 50 | H12: .env.qa.local (also copied here for closed-beta QA team only) | I12: Closed Beta / QA Target | J12: Reset onboarding state between runs if needed. Prefer qa.onboarding@ | K12: Onboarding flows | L12: Anushka, Sultana, Venkat
A13: DISPOSABLE_01 | B13: Disposable | C13: free | D13: Destructive tests (delete account) | E13: qa.disposable@clarify.ai.test | F13: Qa!lSomqsKXtHtOf9-V | G13: 10 | H13: .env.qa.local (also copied here for closed-beta QA team only) | I13: Closed Beta / QA Target | J13: May be deleted — re-seed after | K13: Destructive only | L13: Anushka, Sultana, Venkat
A14: BANNED_USER_01 | B14: Banned | C14: free | D14: Ban enforcement | E14: qa.banned@clarify.ai.test | F14: Qa!nTDcvPqI5RqhAQ3z | G14: 0 | H14: .env.qa.local (also copied here for closed-beta QA team only) | I14: Closed Beta / QA Target | J14: Must remain banned | K14: Login denied | L14: Anushka, Sultana, Venkat
A15: ZERO_CREDIT_01 | B15: Zero credits | C15: pro | D15: Credit exhaustion UX | E15: qa.zero@clarify.ai.test | F15: Qa!VPb4vQOR59Edm1aL | G15: 0 | H15: .env.qa.local (also copied here for closed-beta QA team only) | I15: Closed Beta / QA Target | J15: Keep balance at 0 | K15: AI actions blocked | L15: Anushka, Sultana, Venkat
A16: LOW_CREDIT_01 | B16: Low credits | C16: pro | D16: Low-credit boundary (qa.lowcredit@) | E16: (missing QA_LOW_CREDIT_EMAIL in .env.qa.local) | F16: (missing — run npm run qa:seed-accounts) | H16: .env.qa.local (also copied here for closed-beta QA team only) | I16: Closed Beta / QA Target | J16: Use qa.lowcredit@ only. Do NOT reuse the past-due account for this case. | K16: Warnings + limited actions | L16: Anushka, Sultana, Venkat
A17: EXACT_CREDIT_01 | B17: Exact credits | C17: pro | D17: Exact remaining-credit boundary (qa.exactcredit@) | E17: (missing QA_EXACT_CREDIT_EMAIL in .env.qa.local) | F17: (missing — run npm run qa:seed-accounts) | H17: .env.qa.local (also copied here for closed-beta QA team only) | I17: Closed Beta / QA Target | J17: Keep balance at exact tool cost. Do not drain to zero until TC-CR-005. | K17: Exact-spend then block | L17: Anushka, Sultana, Venkat
A18: SUFFICIENT_CREDIT_01 | B18: Sufficient credits | C18: pro | D18: Happy-path AI consume | E18: qa.pro@clarify.ai.test | F18: Qa!AwHf4rrb5hLYudkp | G18: 1400 | H18: .env.qa.local (also copied here for closed-beta QA team only) | I18: Closed Beta / QA Target | J18: Same as PRO — do not drain to zero | K18: Successful AI flows | L18: Anushka, Sultana, Venkat
A19: HISTORY_USER_01 | B19: User with history | C19: pro | D19: Sessions/reports/compare | E19: qa.pro@clarify.ai.test | F19: Qa!AwHf4rrb5hLYudkp | G19: 1400 | H19: .env.qa.local (also copied here for closed-beta QA team only) | I19: Closed Beta / QA Target | J19: Ensure prior sessions exist or create once | K19: History present | L19: Anushka, Sultana, Venkat
A20: NO_HISTORY_01 | B20: User with no history | C20: free | D20: Empty sessions/analytics | E20: qa.free@clarify.ai.test | F20: Qa!OWORccvwZOiv_jHC | G20: 50 | H20: .env.qa.local (also copied here for closed-beta QA team only) | I20: Closed Beta / QA Target | J20: Use free account with no sessions if possible | K20: Empty states | L20: Anushka, Sultana, Venkat
A21: USER_A_01 | B21: User A (isolation) | C21: pro | D21: Cross-user resource isolation | E21: qa.user-a@clarify.ai.test | F21: Qa!GyjQUOc9hufi4fwF | G21: 1400 | H21: .env.qa.local (also copied here for closed-beta QA team only) | I21: Closed Beta / QA Target | J21: Pair with USER_B_01 | K21: Own data only | L21: Anushka, Sultana, Venkat
A22: USER_B_01 | B22: User B (isolation) | C22: pro | D22: Cross-user resource isolation | E22: qa.user-b@clarify.ai.test | F22: Qa!1WgoI9EiuMHv29qi | G22: 1400 | H22: .env.qa.local (also copied here for closed-beta QA team only) | I22: Closed Beta / QA Target | J22: Pair with USER_A_01 | K22: Own data only | L22: Anushka, Sultana, Venkat
A23: EXPIRED_SESSION_01 | B23: Any valid user | C23: any | D23: Session expiry testing | E23: qa.free@clarify.ai.test | F23: Qa!OWORccvwZOiv_jHC | G23: 50 | H23: .env.qa.local (also copied here for closed-beta QA team only) | I23: Closed Beta / QA Target | J23: Expire session per playbook after login | K23: Re-auth required | L23: Anushka, Sultana, Venkat
A24: MOD_USER_01 | B24: Moderator (if available) | C24: pro | D24: Moderation UI if provisioned | E24: N/A — no login | F24: N/A | G24: — | H24: .env.qa.local (also copied here for closed-beta QA team only) | I24: Closed Beta / QA Target | J24: Skip / N/A if role not seeded | K24: Moderation only | L24: Anushka, Sultana, Venkat
A27: SANDBOX PAYMENT (pre-filled)
A28: Stripe test card | B28: 4242424242424242
A29: Stripe test expiry | B29: 12/34
A30: Stripe test CVC | B30: 123
A31: Payment mode | B31: SANDBOX / TEST ONLY — never live charges unless explicitly approved

Sheet 04 Test Environment
A1: 04 — Test Environment (PRE-FILLED)
A2: Core fields pre-filled. Testers only update Tester name / Test date / Browser version when executing.
A4: Field | B4: Value
A5: Web application URL | B5: https://clarify.ai.sltfinanceindia.com
A6: Admin URL | B6: https://clarify.ai.sltfinanceindia.com/app/admin
A7: Local URL (optional) | B7: http://localhost:5173
A8: Test environment name | B8: Closed Beta / QA Target
